Workbook
Name Acuity_E: Inputs!$B$12
Name Acuity_M: Inputs!$B$11
Name Acuity_N: Inputs!$B$13
Name Arr_E: Inputs!$B$6
Name Arr_M: Inputs!$B$5
Name Arr_N: Inputs!$B$7
Name Avail_Doc: Inputs!$B$28
Name Avail_Nurse: Inputs!$B$29
Name Avail_Tech: Inputs!$B$30
Name BaseAbsence_Doc: Inputs!$B$74
Name BaseAbsence_Nurse: Inputs!$B$75
Name BaseAbsence_Tech: Inputs!$B$76
Name BedCostPerBed: Inputs!$B$40
Name BedHr_E: Inputs!$B$15
Name BedHr_M: Inputs!$B$14
Name BedHr_N: Inputs!$B$16
Name BedHrVariability: Inputs!$B$78
Name BedsAdded: Inputs!$B$41
Name BedsCurrent: Inputs!$B$38
Name BedsMax: Inputs!$B$39
Name Cap_Doc: Inputs!$B$19
Name Cap_Nurse: Inputs!$B$20
Name Cap_Tech: Inputs!$B$21
Name DivertShare: Inputs!$B$55
Name DocAbsence: Inputs!$B$61
Name DocUnavail: Inputs!$B$64
Name ImgBase: Inputs!$B$42
Name ImgExpAdd: Inputs!$B$43
Name ImgExpCost: Inputs!$B$44
Name ImgExpOn: Inputs!$B$45
Name IncidentOn: Inputs!$B$58
Name IncidentSeverity: Inputs!$B$60
Name IncidentShiftNum: Inputs!$B$59
Name LabBase: Inputs!$B$46
Name LabExpAdd: Inputs!$B$47
Name LabExpCost: Inputs!$B$48
Name LabExpOn: Inputs!$B$49
Name NumTrials: Inputs!$B$70
Name NurseAbsence: Inputs!$B$62
Name NurseUnavail: Inputs!$B$65
Name OTCapPct: Inputs!$B$34
Name OTCost_Doc: Inputs!$B$25
Name OTCost_Nurse: Inputs!$B$26
Name OTCost_Tech: Inputs!$B$27
Name P_Complex: Inputs!$B$72
Name P_Incident: Inputs!$B$77
Name P_Normal: Inputs!$B$71
Name P_Severe: Inputs!$B$73
Name PenBedHr: Inputs!$B$54
Name PenDiverted: Inputs!$B$53
Name PenUncovered: Inputs!$B$52
Name RegCost_Doc: Inputs!$B$22
Name RegCost_Nurse: Inputs!$B$23
Name RegCost_Tech: Inputs!$B$24
Name SD_E: Inputs!$B$9
Name SD_M: Inputs!$B$8
Name SD_N: Inputs!$B$10
Name ServiceTarget: Inputs!$B$33
Name ShiftHours: Inputs!$B$35
Name TechAbsence: Inputs!$B$63

Sheet Inputs
A1: Metro Care Hospital
A4: 1. Arrivals & Case Mix (Exhibit 1)
A5: Morning mean arrivals | B5: 85
A6: Evening mean arrivals | B6: 120
A7: Night mean arrivals | B7: 65
A8: Morning arrivals std dev | B8: 12
A9: Evening arrivals std dev | B9: 18
A10: Night arrivals std dev | B10: 10
A11: Morning high-acuity share | B11: 0.22
A12: Evening high-acuity share | B12: 0.28
A13: Night high-acuity share | B13: 0.3
A14: Morning avg bed-hours/patient | B14: 2.1
A15: Evening avg bed-hours/patient | B15: 2.5
A16: Night avg bed-hours/patient | B16: 2.7
A18: 2. Resource Productivity, Cost & Availability (Exhibit 2)
A19: Doctor patients/shift capacity | B19: 18
A20: Nurse patients/shift capacity | B20: 12
A21: Technician patients/shift capacity | B21: 30
A22: Doctor regular cost / shift | B22: 9000
A23: Nurse regular cost / shift | B23: 4500
A24: Technician regular cost / shift | B24: 3500
A25: Doctor overtime cost / shift | B25: 13500
A26: Nurse overtime cost / shift | B26: 6500
A27: Technician overtime cost / shift | B27: 5000
A28: Doctors available (total pool) | B28: 16
A29: Nurses available (total pool) | B29: 28
A30: Technicians available (total pool) | B30: 10
A32: 3. Policy Levers
A33: Service target (% of arrivals covered) | B33: 0.95
A34: Overtime cap (% of regular staff) | B34: 0.25
A35: Shift length (hours) [assumption] | B35: 8
A37: 4. Beds & Diagnostics (Exhibit 3)
A38: Current beds | B38: 34
A39: Max beds | B39: 44
A40: Cost per added bed / day | B40: 1500
A41: BEDS ADDED (0-10) | B41: 0
A42: Imaging base capacity/shift | B42: 52
A43: Imaging expansion size | B43: 10
A44: Imaging expansion cost/day | B44: 18000
A45: EXPAND IMAGING? (1=yes,0=no) | B45: 0
...

Sheet Model
A1: Staffing & Capacity Model
A4: NURSE STAFFING
A5: Shift | B5: Adj. Arrivals | C5: Demand | D5: Req (@ target) | E5: x_min (max OT) | F5: Reduction | G5: Regular staff (x) | H5: Overtime (o) | I5: Unmet (headcount) | J5: Unmet (patients)
A6: Morning | B6: =Arr_M*IF(IncidentOn=1,IF(IncidentShiftNum=1,1+IncidentSeverity,1),1) -> 85 | C6: =B6 -> 85 | D6: =ROUNDUP(ServiceTarget*C6/Cap_Nurse,0) -> 7 | E6: =ROUNDUP(D6/(1+OTCapPct),0) -> 6 | F6: =MIN(MAX($I$9-(F7),0),(D6-E6)) -> 0 | G6: =IF($G$10>0,ROUND(E6*G9/E9,0),D6-F6) -> 7 | H6: =IF($G$10>0,ROUND(OTCapPct*G6,0),F6) -> 0 | I6: =MAX(0,D6-G6-H6) -> 0 | J6: =I6*Cap_Nurse -> 0
A7: Evening | B7: =Arr_E*IF(IncidentOn=1,IF(IncidentShiftNum=2,1+IncidentSeverity,1),1) -> 120 | C7: =B7 -> 120 | D7: =ROUNDUP(ServiceTarget*C7/Cap_Nurse,0) -> 10 | E7: =ROUNDUP(D7/(1+OTCapPct),0) -> 8 | F7: =MIN($I$9,(D7-E7)) -> 0 | G7: =IF($G$10>0,ROUND(E7*G9/E9,0),D7-F7) -> 10 | H7: =IF($G$10>0,ROUND(OTCapPct*G7,0),F7) -> 0 | I7: =MAX(0,D7-G7-H7) -> 0 | J7: =I7*Cap_Nurse -> 0
A8: Night | B8: =Arr_N*IF(IncidentOn=1,IF(IncidentShiftNum=3,1+IncidentSeverity,1),1) -> 65 | C8: =B8 -> 65 | D8: =ROUNDUP(ServiceTarget*C8/Cap_Nurse,0) -> 6 | E8: =ROUNDUP(D8/(1+OTCapPct),0) -> 5 | F8: =MIN(MAX($I$9-(F7+F6),0),(D8-E8)) -> 0 | G8: =IF($G$10>0,ROUND(E8*G9/E9,0),D8-F8) -> 6 | H8: =IF($G$10>0,ROUND(OTCapPct*G8,0),F8) -> 0 | I8: =MAX(0,D8-G8-H8) -> 0 | J8: =I8*Cap_Nurse -> 0
A9: POOL | D9: =SUM(D6:D8) -> 23 | E9: =SUM(E6:E8) -> 19 | F9: Eff. Avail → | G9: =Avail_Nurse*(1-NurseAbsence)*IF(NurseUnavail=1,0,1) -> 28 | H9: Shortfall → | I9: =MAX(0,D9-G9) -> 0
F10: Final short → | G10: =MAX(0,E9-G9) -> 0
A11: Labor cost (reg+OT) | B11: =SUM(G6:G8)*RegCost_Nurse+SUM(H6:H8)*OTCost_Nurse -> 103500
A13: TECHNICIAN STAFFING
A14: Shift | B14: Adj. Arrivals | C14: Demand | D14: Req (@ target) | E14: x_min (max OT) | F14: Reduction | G14: Regular staff (x) | H14: Overtime (o) | I14: Unmet (headcount) | J14: Unmet (patients)
A15: Morning | B15: =Arr_M*IF(IncidentOn=1,IF(IncidentShiftNum=1,1+IncidentSeverity,1),1) -> 85 | C15: =B15 -> 85 | D15: =MAX(ROUNDUP(ServiceTarget*C15/Cap_Tech,0),2) -> 3 | E15: =ROUNDUP(D15/(1+OTCapPct),0) -> 3 | F15: =MIN(MAX($I$18-(F16),0),(D15-E15)) -> 0 | G15: =IF($G$19>0,ROUND(E15*G18/E18,0),D15-F15) -> 3 | H15: =IF($G$19>0,ROUND(OTCapPct*G15,0),F15) -> 0 | I15: =MAX(0,D15-G15-H15) -> 0 | J15: =I15*Cap_Tech -> 0
A16: Evening | B16: =Arr_E*IF(IncidentOn=1,IF(IncidentShiftNum=2,1+IncidentSeverity,1),1) -> 120 | C16: =B16 -> 120 | D16: =MAX(ROUNDUP(ServiceTarget*C16/Cap_Tech,0),2) -> 4 | E16: =ROUNDUP(D16/(1+OTCapPct),0) -> 4 | F16: =MIN($I$18,(D16-E16)) -> 0 | G16: =IF($G$19>0,ROUND(E16*G18/E18,0),D16-F16) -> 4 | H16: =IF($G$19>0,ROUND(OTCapPct*G16,0),F16) -> 0 | I16: =MAX(0,D16-G16-H16) -> 0 | J16: =I16*Cap_Tech -> 0
A17: Night | B17: =Arr_N*IF(IncidentOn=1,IF(IncidentShiftNum=3,1+IncidentSeverity,1),1) -> 65 | C17: =B17 -> 65 | D17: =MAX(ROUNDUP(ServiceTarget*C17/Cap_Tech,0),2) -> 3 | E17: =ROUNDUP(D17/(1+OTCapPct),0) -> 3 | F17: =MIN(MAX($I$18-(F16+F15),0),(D17-E17)) -> 0 | G17: =IF($G$19>0,ROUND(E17*G18/E18,0),D17-F17) -> 3 | H17: =IF($G$19>0,ROUND(OTCapPct*G17,0),F17) -> 0 | I17: =MAX(0,D17-G17-H17) -> 0 | J17: =I17*Cap_Tech -> 0
A18: POOL | D18: =SUM(D15:D17) -> 10 | E18: =SUM(E15:E17) -> 10 | F18: Eff. Avail → | G18: =Avail_Tech*(1-TechAbsence)*IF(TechUnavail=1,0,1) -> 10 | H18: Shortfall → | I18: =MAX(0,D18-G18) -> 0
F19: Final short → | G19: =MAX(0,E18-G18) -> 0
A20: Labor cost (reg+OT) | B20: =SUM(G15:G17)*RegCost_Tech+SUM(H15:H17)*OTCost_Tech -> 35000
A22: DOCTOR STAFFING
A23: Shift | B23: Adj. Arrivals | C23: Demand | D23: Req (@ target) | E23: x_min (max OT) | F23: Reduction | G23: Regular staff (x) | H23: Overtime (o) | I23: Unmet (headcount) | J23: Unmet (patients)
A24: Morning | B24: =Arr_M*IF(IncidentOn=1,IF(IncidentShiftNum=1,1+IncidentSeverity,1),1) -> 85 | C24: =B24*(1+0.5*Acuity_M) -> 94.35 | D24: =MAX(ROUNDUP(ServiceTarget*C24/Cap_Doc,0),ROUNDUP(0.5*(G6+H6),0)) -> 5 | E24: =ROUNDUP(D24/(1+OTCapPct),0) -> 4 | F24: =MIN(MAX($I$27-(F25),0),(D24-E24)) -> 0 | G24: =IF($G$28>0,ROUND(E24*G27/E27,0),D24-F24) -> 5 | H24: =IF($G$28>0,ROUND(OTCapPct*G24,0),F24) -> 0 | I24: =MAX(0,D24-G24-H24) -> 0 | J24: =I24*Cap_Doc -> 0
A25: Evening | B25: =Arr_E*IF(IncidentOn=1,IF(IncidentShiftNum=2,1+IncidentSeverity,1),1) -> 120 | C25: =B25*(1+0.5*Acuity_E) -> 136.8 | D25: =MAX(ROUNDUP(ServiceTarget*C25/Cap_Doc,0),ROUNDUP(0.5*(G7+H7),0)) -> 8 | E25: =ROUNDUP(D25/(1+OTCapPct),0) -> 7 | F25: =MIN($I$27,(D25-E25)) -> 1 | G25: =IF($G$28>0,ROUND(E25*G27/E27,0),D25-F25) -> 7 | H25: =IF($G$28>0,ROUND(OTCapPct*G25,0),F25) -> 1 | I25: =MAX(0,D25-G25-H25) -> 0 | J25: =I25*Cap_Doc -> 0
A26: Night | B26: =Arr_N*IF(IncidentOn=1,IF(IncidentShiftNum=3,1+IncidentSeverity,1),1) -> 65 | C26: =B26*(1+0.5*Acuity_N) -> 74.75 | D26: =MAX(ROUNDUP(ServiceTarget*C26/Cap_Doc,0),MAX(ROUNDUP(0.5*(G8+H8),0),4)) -> 4 | E26: =ROUNDUP(D26/(1+OTCapPct),0) -> 4 | F26: =MIN(MAX($I$27-(F25+F24),0),(D26-E26)) -> 0 | G26: =IF($G$28>0,ROUND(E26*G27/E27,0),D26-F26) -> 4 | H26: =IF($G$28>0,ROUND(OTCapPct*G26,0),F26) -> 0 | I26: =MAX(0,D26-G26-H26) -> 0 | J26: =I26*Cap_Doc -> 0
A27: POOL | D27: =SUM(D24:D26) -> 17 | E27: =SUM(E24:E26) -> 15 | F27: Eff. Avail → | G27: =Avail_Doc*(1-DocAbsence)*IF(DocUnavail=1,0,1) -> 16 | H27: Shortfall → | I27: =MAX(0,D27-G27) -> 1
F28: Final short → | G28: =MAX(0,E27-G27) -> 0
A29: Labor cost (reg+OT) | B29: =SUM(G24:G26)*RegCost_Doc+SUM(H24:H26)*OTCost_Doc -> 157500
A31: BED CAPACITY
A32: Shift | B32: Adj. Arrivals | C32: Bed Capacity (patients) | D32: Bed-Hrs Available | E32: Bed-Hrs Needed | F32: Bed-Hr Shortfall | G32: Unmet (patients, beds)
A33: Morning | B33: =Arr_M*IF(IncidentOn=1,IF(IncidentShiftNum=1,1+IncidentSeverity,1),1) -> 85 | C33: =(BedsCurrent+BedsAdded)*ShiftHours/BedHr_M -> 129.52381 | D33: =(BedsCurrent+BedsAdded)*ShiftHours -> 272 | E33: =ServiceTarget*B33*BedHr_M -> 169.575 | F33: =MAX(0,E33-D33) -> 0 | G33: =MAX(0,ServiceTarget*B33-C33) -> 0
A34: Evening | B34: =Arr_E*IF(IncidentOn=1,IF(IncidentShiftNum=2,1+IncidentSeverity,1),1) -> 120 | C34: =(BedsCurrent+BedsAdded)*ShiftHours/BedHr_E -> 108.8 | D34: =(BedsCurrent+BedsAdded)*ShiftHours -> 272 | E34: =ServiceTarget*B34*BedHr_E -> 285 | F34: =MAX(0,E34-D34) -> 13 | G34: =MAX(0,ServiceTarget*B34-C34) -> 5.2
A35: Night | B35: =Arr_N*IF(IncidentOn=1,IF(IncidentShiftNum=3,1+IncidentSeverity,1),1) -> 65 | C35: =(BedsCurrent+BedsAdded)*ShiftHours/BedHr_N -> 100.74074 | D35: =(BedsCurrent+BedsAdded)*ShiftHours -> 272 | E35: =ServiceTarget*B35*BedHr_N -> 166.725 | F35: =MAX(0,E35-D35) -> 0 | G35: =MAX(0,ServiceTarget*B35-C35) -> 0
A36: TOTAL | D36: =SUM(D33:D35) -> 816 | E36: =SUM(E33:E35) -> 621.3 | F36: =SUM(F33:F35) -> 13 | G36: =SUM(G33:G35) -> 5.2
A37: Bed expansion cost | B37: =BedsAdded*BedCostPerBed -> 0
A39: DIAGNOSTIC CAPACITY (Imaging & Lab)
A40: Shift | B40: Adj. Arrivals | C40: Imaging Demand | D40: Imaging Capacity | E40: Imaging Shortfall (patients) | F40: Lab Demand | G40: Lab Capacity | H40: Lab Shortfall (patients)
A41: Morning | B41: =Arr_M*IF(IncidentOn=1,IF(IncidentShiftNum=1,1+IncidentSeverity,1),1) -> 85 | C41: =ServiceTarget*B41*Acuity_M -> 17.765 | D41: =ImgBase+ImgExpOn*ImgExpAdd -> 52 | E41: =MAX(0,C41-D41) -> 0 | F41: =ServiceTarget*B41 -> 80.75 | G41: =LabBase+LabExpOn*LabExpAdd -> 95 | H41: =MAX(0,F41-G41) -> 0
A42: Evening | B42: =Arr_E*IF(IncidentOn=1,IF(IncidentShiftNum=2,1+IncidentSeverity,1),1) -> 120 | C42: =ServiceTarget*B42*Acuity_E -> 31.92 | D42: =ImgBase+ImgExpOn*ImgExpAdd -> 52 | E42: =MAX(0,C42-D42) -> 0 | F42: =ServiceTarget*B42 -> 114 | G42: =LabBase+LabExpOn*LabExpAdd -> 95 | H42: =MAX(0,F42-G42) -> 19
A43: Night | B43: =Arr_N*IF(IncidentOn=1,IF(IncidentShiftNum=3,1+IncidentSeverity,1),1) -> 65 | C43: =ServiceTarget*B43*Acuity_N -> 18.525 | D43: =ImgBase+ImgExpOn*ImgExpAdd -> 52 | E43: =MAX(0,C43-D43) -> 0 | F43: =ServiceTarget*B43 -> 61.75 | G43: =LabBase+LabExpOn*LabExpAdd -> 95 | H43: =MAX(0,F43-G43) -> 0
A44: TOTAL | E44: =SUM(E41:E43) -> 0 | H44: =SUM(H41:H43) -> 19
A45: Diagnostic expansion cost | B45: =ImgExpOn*ImgExpCost+LabExpOn*LabExpCost -> 0
A47: BOTTLENECK ANALYSIS — SYSTEM-WIDE UNMET DEMAND
...

Sheet Strategy Comparison
A1: Strategy Comparison : Minimalised vs Balanced vs Resilient
A4: Policy Lever | B4: Minimalized | C4: Balanced (moderate buffer) | D4: Resilient (capacity-expanded)
A5: Service target | B5: 0.85 | C5: 0.95 | D5: 0.99
A6: Beds added | B6: 0 | C6: 3 | D6: 6
A7: Expand imaging? (1/0) | B7: 0 | C7: 0 | D7: 1
A8: Expand lab? (1/0) | B8: 0 | C8: 1 | D8: 1
A10: Resulting Cost & Service Levels (approximate)
A11: Total labor cost (regular + OT) | B11: =(MIN((CEILING((B5)*(Arr_M*(1+0.5*Acuity_M))/Cap_Doc,1)+CEILING((B5)*(Arr_E*(1+0.5*Acuity_E))/Cap_Doc,1)+CEILING((B5)*(Arr_N*(1+0.5*Acuity_N))/Cap_Doc,1)),Avail_Doc))*RegCost_Doc+(MIN(MAX((CEILING((B5)*(Arr_M*(1+0.5*Acuity_M))/Cap_Doc,1)+CEILING((B5)*(Arr_E*(1+0.5*Acuity_E))/Cap_Doc,1)+CEILING((B5)*(Arr_N*(1+0.5*Acuity_N))/Cap_Doc,1))-Avail_Doc,0),OTCapPct*MIN((CEILING((B5)*(Arr_M*(1+0.5*Acuity_M))/Cap_Doc,1)+CEILING((B5)*(Arr_E*(1+0.5*Acuity_E))/Cap_Doc,1)+CEILING((B5)*(Arr_N*(1+0.5*Acuity_N))/Cap_Doc,1)),Avail_Doc)))*OTCost_Doc+(MIN((CEILING((B5)*(Arr_M)/Cap_Nurse,1)+CEILING((B5)*(Arr_E)/Cap_Nurse,1)+CEILING((B5)*(Arr_N)/Cap_Nurse,1)),Avail_Nurse))*RegCost_Nurse+(MIN(MAX((CEILING((B5)*(Arr_M)/Cap_Nurse,1)+CEILING((B5)*(Arr_E)/Cap_Nurse,1)+CEILING((B5)*(Arr_N)/Cap_Nurse,1))-Avail_Nurse,0),OTCapPct*MIN((CEILING((B5)*(Arr_M)/Cap_Nurse,1)+CEILING((B5)*(Arr_E)/Cap_Nurse,1)+CEILING((B5)*(Arr_N)/Cap_Nurse,1)),Avail_Nurse)))*OTCost_Nurse+(MIN((CEILING((B5)*(Arr_M)/Cap_Tech,1)+CEILING((B5)*(Arr_E)/Cap_Tech,1)+CEILING((B5)*(Arr_N)/Cap_Tech,1)),Avail_Tech))*RegCost_Tech+(MIN(MAX((CEILING((B5)*(Arr_M)/Cap_Tech,1)+CEILING((B5)*(Arr_E)/Cap_Tech,1)+CEILING((B5)*(Arr_N)/Cap_Tech,1))-Avail_Tech,0),OTCapPct*MIN((CEILING((B5)*(Arr_M)/Cap_Tech,1)+CEILING((B5)*(Arr_E)/Cap_Tech,1)+CEILING((B5)*(Arr_N)/Cap_Tech,1)),Avail_Tech)))*OTCost_Tech -> 270000 | C11: =(MIN((CEILING((C5)*(Arr_M*(1+0.5*Acuity_M))/Cap_Doc,1)+CEILING((C5)*(Arr_E*(1+0.5*Acuity_E))/Cap_Doc,1)+CEILING((C5)*(Arr_N*(1+0.5*Acuity_N))/Cap_Doc,1)),Avail_Doc))*RegCost_Doc+(MIN(MAX((CEILING((C5)*(Arr_M*(1+0.5*Acuity_M))/Cap_Doc,1)+CEILING((C5)*(Arr_E*(1+0.5*Acuity_E))/Cap_Doc,1)+CEILING((C5)*(Arr_N*(1+0.5*Acuity_N))/Cap_Doc,1))-Avail_Doc,0),OTCapPct*MIN((CEILING((C5)*(Arr_M*(1+0.5*Acuity_M))/Cap_Doc,1)+CEILING((C5)*(Arr_E*(1+0.5*Acuity_E))/Cap_Doc,1)+CEILING((C5)*(Arr_N*(1+0.5*Acuity_N))/Cap_Doc,1)),Avail_Doc)))*OTCost_Doc+(MIN((CEILING((C5)*(Arr_M)/Cap_Nurse,1)+CEILING((C5)*(Arr_E)/Cap_Nurse,1)+CEILING((C5)*(Arr_N)/Cap_Nurse,1)),Avail_Nurse))*RegCost_Nurse+(MIN(MAX((CEILING((C5)*(Arr_M)/Cap_Nurse,1)+CEILING((C5)*(Arr_E)/Cap_Nurse,1)+CEILING((C5)*(Arr_N)/Cap_Nurse,1))-Avail_Nurse,0),OTCapPct*MIN((CEILING((C5)*(Arr_M)/Cap_Nurse,1)+CEILING((C5)*(Arr_E)/Cap_Nurse,1)+CEILING((C5)*(Arr_N)/Cap_Nurse,1)),Avail_Nurse)))*OTCost_Nurse+(MIN((CEILING((C5)*(Arr_M)/Cap_Tech,1)+CEILING((C5)*(Arr_E)/Cap_Tech,1)+CEILING((C5)*(Arr_N)/Cap_Tech,1)),Avail_Tech))*RegCost_Tech+(MIN(MAX((CEILING((C5)*(Arr_M)/Cap_Tech,1)+CEILING((C5)*(Arr_E)/Cap_Tech,1)+CEILING((C5)*(Arr_N)/Cap_Tech,1))-Avail_Tech,0),OTCapPct*MIN((CEILING((C5)*(Arr_M)/Cap_Tech,1)+CEILING((C5)*(Arr_E)/Cap_Tech,1)+CEILING((C5)*(Arr_N)/Cap_Tech,1)),Avail_Tech)))*OTCost_Tech -> 296000 | D11: =(MIN((CEILING((D5)*(Arr_M*(1+0.5*Acuity_M))/Cap_Doc,1)+CEILING((D5)*(Arr_E*(1+0.5*Acuity_E))/Cap_Doc,1)+CEILING((D5)*(Arr_N*(1+0.5*Acuity_N))/Cap_Doc,1)),Avail_Doc))*RegCost_Doc+(MIN(MAX((CEILING((D5)*(Arr_M*(1+0.5*Acuity_M))/Cap_Doc,1)+CEILING((D5)*(Arr_E*(1+0.5*Acuity_E))/Cap_Doc,1)+CEILING((D5)*(Arr_N*(1+0.5*Acuity_N))/Cap_Doc,1))-Avail_Doc,0),OTCapPct*MIN((CEILING((D5)*(Arr_M*(1+0.5*Acuity_M))/Cap_Doc,1)+CEILING((D5)*(Arr_E*(1+0.5*Acuity_E))/Cap_Doc,1)+CEILING((D5)*(Arr_N*(1+0.5*Acuity_N))/Cap_Doc,1)),Avail_Doc)))*OTCost_Doc+(MIN((CEILING((D5)*(Arr_M)/Cap_Nurse,1)+CEILING((D5)*(Arr_E)/Cap_Nurse,1)+CEILING((D5)*(Arr_N)/Cap_Nurse,1)),Avail_Nurse))*RegCost_Nurse+(MIN(MAX((CEILING((D5)*(Arr_M)/Cap_Nurse,1)+CEILING((D5)*(Arr_E)/Cap_Nurse,1)+CEILING((D5)*(Arr_N)/Cap_Nurse,1))-Avail_Nurse,0),OTCapPct*MIN((CEILING((D5)*(Arr_M)/Cap_Nurse,1)+CEILING((D5)*(Arr_E)/Cap_Nurse,1)+CEILING((D5)*(Arr_N)/Cap_Nurse,1)),Avail_Nurse)))*OTCost_Nurse+(MIN((CEILING((D5)*(Arr_M)/Cap_Tech,1)+CEILING((D5)*(Arr_E)/Cap_Tech,1)+CEILING((D5)*(Arr_N)/Cap_Tech,1)),Avail_Tech))*RegCost_Tech+(MIN(MAX((CEILING((D5)*(Arr_M)/Cap_Tech,1)+CEILING((D5)*(Arr_E)/Cap_Tech,1)+CEILING((D5)*(Arr_N)/Cap_Tech,1))-Avail_Tech,0),OTCapPct*MIN((CEILING((D5)*(Arr_M)/Cap_Tech,1)+CEILING((D5)*(Arr_E)/Cap_Tech,1)+CEILING((D5)*(Arr_N)/Cap_Tech,1)),Avail_Tech)))*OTCost_Tech -> 327500
A12: Capacity expansion cost (beds+diag) | B12: =B6*BedCostPerBed+B7*ImgExpCost+B8*LabExpCost -> 0 | C12: =C6*BedCostPerBed+C7*ImgExpCost+C8*LabExpCost -> 16500 | D12: =D6*BedCostPerBed+D7*ImgExpCost+D8*LabExpCost -> 39000
A13: Est. uncovered patients / day | B13: =(MAX(0,((CEILING((B5)*(Arr_M*(1+0.5*Acuity_M))/Cap_Doc,1)+CEILING((B5)*(Arr_E*(1+0.5*Acuity_E))/Cap_Doc,1)+CEILING((B5)*(Arr_N*(1+0.5*Acuity_N))/Cap_Doc,1)))-Avail_Doc-OTCapPct*MIN((CEILING((B5)*(Arr_M*(1+0.5*Acuity_M))/Cap_Doc,1)+CEILING((B5)*(Arr_E*(1+0.5*Acuity_E))/Cap_Doc,1)+CEILING((B5)*(Arr_N*(1+0.5*Acuity_N))/Cap_Doc,1)),Avail_Doc)))*Cap_Doc+(MAX(0,((CEILING((B5)*(Arr_M)/Cap_Nurse,1)+CEILING((B5)*(Arr_E)/Cap_Nurse,1)+CEILING((B5)*(Arr_N)/Cap_Nurse,1)))-Avail_Nurse-OTCapPct*MIN((CEILING((B5)*(Arr_M)/Cap_Nurse,1)+CEILING((B5)*(Arr_E)/Cap_Nurse,1)+CEILING((B5)*(Arr_N)/Cap_Nurse,1)),Avail_Nurse)))*Cap_Nurse+(MAX(0,((CEILING((B5)*(Arr_M)/Cap_Tech,1)+CEILING((B5)*(Arr_E)/Cap_Tech,1)+CEILING((B5)*(Arr_N)/Cap_Tech,1)))-Avail_Tech-OTCapPct*MIN((CEILING((B5)*(Arr_M)/Cap_Tech,1)+CEILING((B5)*(Arr_E)/Cap_Tech,1)+CEILING((B5)*(Arr_N)/Cap_Tech,1)),Avail_Tech)))*Cap_Tech+(MAX(0,(B5)*Arr_M-(B6+BedsCurrent)*ShiftHours/BedHr_M)+MAX(0,(B5)*Arr_E-(B6+BedsCurrent)*ShiftHours/BedHr_E)+MAX(0,(B5)*Arr_N-(B6+BedsCurrent)*ShiftHours/BedHr_N))+(MAX(0,(B5)*Arr_M*Acuity_M-(ImgBase+B7*ImgExpAdd))+MAX(0,(B5)*Arr_E*Acuity_E-(ImgBase+B7*ImgExpAdd))+MAX(0,(B5)*Arr_N*Acuity_N-(ImgBase+B7*ImgExpAdd)))+(MAX(0,(B5)*Arr_M-(LabBase+B8*LabExpAdd))+MAX(0,(B5)*Arr_E-(LabBase+B8*LabExpAdd))+MAX(0,(B5)*Arr_N-(LabBase+B8*LabExpAdd))) -> 7 | C13: =(MAX(0,((CEILING((C5)*(Arr_M*(1+0.5*Acuity_M))/Cap_Doc,1)+CEILING((C5)*(Arr_E*(1+0.5*Acuity_E))/Cap_Doc,1)+CEILING((C5)*(Arr_N*(1+0.5*Acuity_N))/Cap_Doc,1)))-Avail_Doc-OTCapPct*MIN((CEILING((C5)*(Arr_M*(1+0.5*Acuity_M))/Cap_Doc,1)+CEILING((C5)*(Arr_E*(1+0.5*Acuity_E))/Cap_Doc,1)+CEILING((C5)*(Arr_N*(1+0.5*Acuity_N))/Cap_Doc,1)),Avail_Doc)))*Cap_Doc+(MAX(0,((CEILING((C5)*(Arr_M)/Cap_Nurse,1)+CEILING((C5)*(Arr_E)/Cap_Nurse,1)+CEILING((C5)*(Arr_N)/Cap_Nurse,1)))-Avail_Nurse-OTCapPct*MIN((CEILING((C5)*(Arr_M)/Cap_Nurse,1)+CEILING((C5)*(Arr_E)/Cap_Nurse,1)+CEILING((C5)*(Arr_N)/Cap_Nurse,1)),Avail_Nurse)))*Cap_Nurse+(MAX(0,((CEILING((C5)*(Arr_M)/Cap_Tech,1)+CEILING((C5)*(Arr_E)/Cap_Tech,1)+CEILING((C5)*(Arr_N)/Cap_Tech,1)))-Avail_Tech-OTCapPct*MIN((CEILING((C5)*(Arr_M)/Cap_Tech,1)+CEILING((C5)*(Arr_E)/Cap_Tech,1)+CEILING((C5)*(Arr_N)/Cap_Tech,1)),Avail_Tech)))*Cap_Tech+(MAX(0,(C5)*Arr_M-(C6+BedsCurrent)*ShiftHours/BedHr_M)+MAX(0,(C5)*Arr_E-(C6+BedsCurrent)*ShiftHours/BedHr_E)+MAX(0,(C5)*Arr_N-(C6+BedsCurrent)*ShiftHours/BedHr_N))+(MAX(0,(C5)*Arr_M*Acuity_M-(ImgBase+C7*ImgExpAdd))+MAX(0,(C5)*Arr_E*Acuity_E-(ImgBase+C7*ImgExpAdd))+MAX(0,(C5)*Arr_N*Acuity_N-(ImgBase+C7*ImgExpAdd)))+(MAX(0,(C5)*Arr_M-(LabBase+C8*LabExpAdd))+MAX(0,(C5)*Arr_E-(LabBase+C8*LabExpAdd))+MAX(0,(C5)*Arr_N-(LabBase+C8*LabExpAdd))) -> 0 | D13: =(MAX(0,((CEILING((D5)*(Arr_M*(1+0.5*Acuity_M))/Cap_Doc,1)+CEILING((D5)*(Arr_E*(1+0.5*Acuity_E))/Cap_Doc,1)+CEILING((D5)*(Arr_N*(1+0.5*Acuity_N))/Cap_Doc,1)))-Avail_Doc-OTCapPct*MIN((CEILING((D5)*(Arr_M*(1+0.5*Acuity_M))/Cap_Doc,1)+CEILING((D5)*(Arr_E*(1+0.5*Acuity_E))/Cap_Doc,1)+CEILING((D5)*(Arr_N*(1+0.5*Acuity_N))/Cap_Doc,1)),Avail_Doc)))*Cap_Doc+(MAX(0,((CEILING((D5)*(Arr_M)/Cap_Nurse,1)+CEILING((D5)*(Arr_E)/Cap_Nurse,1)+CEILING((D5)*(Arr_N)/Cap_Nurse,1)))-Avail_Nurse-OTCapPct*MIN((CEILING((D5)*(Arr_M)/Cap_Nurse,1)+CEILING((D5)*(Arr_E)/Cap_Nurse,1)+CEILING((D5)*(Arr_N)/Cap_Nurse,1)),Avail_Nurse)))*Cap_Nurse+(MAX(0,((CEILING((D5)*(Arr_M)/Cap_Tech,1)+CEILING((D5)*(Arr_E)/Cap_Tech,1)+CEILING((D5)*(Arr_N)/Cap_Tech,1)))-Avail_Tech-OTCapPct*MIN((CEILING((D5)*(Arr_M)/Cap_Tech,1)+CEILING((D5)*(Arr_E)/Cap_Tech,1)+CEILING((D5)*(Arr_N)/Cap_Tech,1)),Avail_Tech)))*Cap_Tech+(MAX(0,(D5)*Arr_M-(D6+BedsCurrent)*ShiftHours/BedHr_M)+MAX(0,(D5)*Arr_E-(D6+BedsCurrent)*ShiftHours/BedHr_E)+MAX(0,(D5)*Arr_N-(D6+BedsCurrent)*ShiftHours/BedHr_N))+(MAX(0,(D5)*Arr_M*Acuity_M-(ImgBase+D7*ImgExpAdd))+MAX(0,(D5)*Arr_E*Acuity_E-(ImgBase+D7*ImgExpAdd))+MAX(0,(D5)*Arr_N*Acuity_N-(ImgBase+D7*ImgExpAdd)))+(MAX(0,(D5)*Arr_M-(LabBase+D8*LabExpAdd))+MAX(0,(D5)*Arr_E-(LabBase+D8*LabExpAdd))+MAX(0,(D5)*Arr_N-(LabBase+D8*LabExpAdd))) -> 3.8
A14: Penalty cost (uncovered + diversion) | B14: =B13*(PenUncovered*(1-DivertShare)+PenDiverted*DivertShare) -> 49350 | C14: =C13*(PenUncovered*(1-DivertShare)+PenDiverted*DivertShare) -> 0 | D14: =D13*(PenUncovered*(1-DivertShare)+PenDiverted*DivertShare) -> 26790
A15: TOTAL EXPECTED DAILY COST | B15: =B11+B12+B14 -> 319350 | C15: =C11+C12+C14 -> 312500 | D15: =D11+D12+D14 -> 393290
A16: Est. arrival coverage (%) | B16: =1-B13/(Arr_M+Arr_E+Arr_N) -> 0.97407407 | C16: =1-C13/(Arr_M+Arr_E+Arr_N) -> 1 | D16: =1-D13/(Arr_M+Arr_E+Arr_N) -> 0.98592593

Sheet Sensitivity
A1: Sensitivity Analysis
A4: 1. Service Target Sensitivity (Task 6)
A5: Service Target | B5: Total Daily Cost | C5: Coverage % | D5: Uncovered Patients/Day | E5: Δ Cost vs Current
A6: 0.8 | B6: =((MIN((CEILING((0.8)*(Arr_M*(1+0.5*Acuity_M))/Cap_Doc,1)+CEILING((0.8)*(Arr_E*(1+0.5*Acuity_E))/Cap_Doc,1)+CEILING((0.8)*(Arr_N*(1+0.5*Acuity_N))/Cap_Doc,1)),Avail_Doc))*RegCost_Doc+(MIN(MAX((CEILING((0.8)*(Arr_M*(1+0.5*Acuity_M))/Cap_Doc,1)+CEILING((0.8)*(Arr_E*(1+0.5*Acuity_E))/Cap_Doc,1)+CEILING((0.8)*(Arr_N*(1+0.5*Acuity_N))/Cap_Doc,1))-Avail_Doc,0),(OTCapPct)*MIN((CEILING((0.8)*(Arr_M*(1+0.5*Acuity_M))/Cap_Doc,1)+CEILING((0.8)*(Arr_E*(1+0.5*Acuity_E))/Cap_Doc,1)+CEILING((0.8)*(Arr_N*(1+0.5*Acuity_N))/Cap_Doc,1)),Avail_Doc)))*OTCost_Doc+(MIN((CEILING((0.8)*(Arr_M)/Cap_Nurse,1)+CEILING((0.8)*(Arr_E)/Cap_Nurse,1)+CEILING((0.8)*(Arr_N)/Cap_Nurse,1)),Avail_Nurse))*RegCost_Nurse+(MIN(MAX((CEILING((0.8)*(Arr_M)/Cap_Nurse,1)+CEILING((0.8)*(Arr_E)/Cap_Nurse,1)+CEILING((0.8)*(Arr_N)/Cap_Nurse,1))-Avail_Nurse,0),(OTCapPct)*MIN((CEILING((0.8)*(Arr_M)/Cap_Nurse,1)+CEILING((0.8)*(Arr_E)/Cap_Nurse,1)+CEILING((0.8)*(Arr_N)/Cap_Nurse,1)),Avail_Nurse)))*OTCost_Nurse+(MIN((CEILING((0.8)*(Arr_M)/Cap_Tech,1)+CEILING((0.8)*(Arr_E)/Cap_Tech,1)+CEILING((0.8)*(Arr_N)/Cap_Tech,1)),Avail_Tech))*RegCost_Tech+(MIN(MAX((CEILING((0.8)*(Arr_M)/Cap_Tech,1)+CEILING((0.8)*(Arr_E)/Cap_Tech,1)+CEILING((0.8)*(Arr_N)/Cap_Tech,1))-Avail_Tech,0),(OTCapPct)*MIN((CEILING((0.8)*(Arr_M)/Cap_Tech,1)+CEILING((0.8)*(Arr_E)/Cap_Tech,1)+CEILING((0.8)*(Arr_N)/Cap_Tech,1)),Avail_Tech)))*OTCost_Tech)+((BedsAdded)*BedCostPerBed+(ImgExpOn)*ImgExpCost+(LabExpOn)*LabExpCost)+(((MAX(0,((CEILING((0.8)*(Arr_M*(1+0.5*Acuity_M))/Cap_Doc,1)+CEILING((0.8)*(Arr_E*(1+0.5*Acuity_E))/Cap_Doc,1)+CEILING((0.8)*(Arr_N*(1+0.5*Acuity_N))/Cap_Doc,1)))-Avail_Doc-(OTCapPct)*MIN((CEILING((0.8)*(Arr_M*(1+0.5*Acuity_M))/Cap_Doc,1)+CEILING((0.8)*(Arr_E*(1+0.5*Acuity_E))/Cap_Doc,1)+CEILING((0.8)*(Arr_N*(1+0.5*Acuity_N))/Cap_Doc,1)),Avail_Doc)))*Cap_Doc+(MAX(0,((CEILING((0.8)*(Arr_M)/Cap_Nurse,1)+CEILING((0.8)*(Arr_E)/Cap_Nurse,1)+CEILING((0.8)*(Arr_N)/Cap_Nurse,1)))-Avail_Nurse-(OTCapPct)*MIN((CEILING((0.8)*(Arr_M)/Cap_Nurse,1)+CEILING((0.8)*(Arr_E)/Cap_Nurse,1)+CEILING((0.8)*(Arr_N)/Cap_Nurse,1)),Avail_Nurse)))*Cap_Nurse+(MAX(0,((CEILING((0.8)*(Arr_M)/Cap_Tech,1)+CEILING((0.8)*(Arr_E)/Cap_Tech,1)+CEILING((0.8)*(Arr_N)/Cap_Tech,1)))-Avail_Tech-(OTCapPct)*MIN((CEILING((0.8)*(Arr_M)/Cap_Tech,1)+CEILING((0.8)*(Arr_E)/Cap_Tech,1)+CEILING((0.8)*(Arr_N)/Cap_Tech,1)),Avail_Tech)))*Cap_Tech+(MAX(0,(0.8)*Arr_M-(BedsAdded+BedsCurrent)*ShiftHours/BedHr_M)+MAX(0,(0.8)*Arr_E-(BedsAdded+BedsCurrent)*ShiftHours/BedHr_E)+MAX(0,(0.8)*Arr_N-(BedsAdded+BedsCurrent)*ShiftHours/BedHr_N))+(MAX(0,(0.8)*Arr_M*Acuity_M-(ImgBase+(ImgExpOn)*ImgExpAdd))+MAX(0,(0.8)*Arr_E*Acuity_E-(ImgBase+(ImgExpOn)*ImgExpAdd))+MAX(0,(0.8)*Arr_N*Acuity_N-(ImgBase+(ImgExpOn)*ImgExpAdd)))+(MAX(0,(0.8)*Arr_M-(LabBase+(LabExpOn)*LabExpAdd))+MAX(0,(0.8)*Arr_E-(LabBase+(LabExpOn)*LabExpAdd))+MAX(0,(0.8)*Arr_N-(LabBase+(LabExpOn)*LabExpAdd))))*(PenUncovered*(1-DivertShare)+PenDiverted*DivertShare)) -> 268050 | C6: =1-((MAX(0,((CEILING((0.8)*(Arr_M*(1+0.5*Acuity_M))/Cap_Doc,1)+CEILING((0.8)*(Arr_E*(1+0.5*Acuity_E))/Cap_Doc,1)+CEILING((0.8)*(Arr_N*(1+0.5*Acuity_N))/Cap_Doc,1)))-Avail_Doc-(OTCapPct)*MIN((CEILING((0.8)*(Arr_M*(1+0.5*Acuity_M))/Cap_Doc,1)+CEILING((0.8)*(Arr_E*(1+0.5*Acuity_E))/Cap_Doc,1)+CEILING((0.8)*(Arr_N*(1+0.5*Acuity_N))/Cap_Doc,1)),Avail_Doc)))*Cap_Doc+(MAX(0,((CEILING((0.8)*(Arr_M)/Cap_Nurse,1)+CEILING((0.8)*(Arr_E)/Cap_Nurse,1)+CEILING((0.8)*(Arr_N)/Cap_Nurse,1)))-Avail_Nurse-(OTCapPct)*MIN((CEILING((0.8)*(Arr_M)/Cap_Nurse,1)+CEILING((0.8)*(Arr_E)/Cap_Nurse,1)+CEILING((0.8)*(Arr_N)/Cap_Nurse,1)),Avail_Nurse)))*Cap_Nurse+(MAX(0,((CEILING((0.8)*(Arr_M)/Cap_Tech,1)+CEILING((0.8)*(Arr_E)/Cap_Tech,1)+CEILING((0.8)*(Arr_N)/Cap_Tech,1)))-Avail_Tech-(OTCapPct)*MIN((CEILING((0.8)*(Arr_M)/Cap_Tech,1)+CEILING((0.8)*(Arr_E)/Cap_Tech,1)+CEILING((0.8)*(Arr_N)/Cap_Tech,1)),Avail_Tech)))*Cap_Tech+(MAX(0,(0.8)*Arr_M-(BedsAdded+BedsCurrent)*ShiftHours/BedHr_M)+MAX(0,(0.8)*Arr_E-(BedsAdded+BedsCurrent)*ShiftHours/BedHr_E)+MAX(0,(0.8)*Arr_N-(BedsAdded+BedsCurrent)*ShiftHours/BedHr_N))+(MAX(0,(0.8)*Arr_M*Acuity_M-(ImgBase+(ImgExpOn)*ImgExpAdd))+MAX(0,(0.8)*Arr_E*Acuity_E-(ImgBase+(ImgExpOn)*ImgExpAdd))+MAX(0,(0.8)*Arr_N*Acuity_N-(ImgBase+(ImgExpOn)*ImgExpAdd)))+(MAX(0,(0.8)*Arr_M-(LabBase+(LabExpOn)*LabExpAdd))+MAX(0,(0.8)*Arr_E-(LabBase+(LabExpOn)*LabExpAdd))+MAX(0,(0.8)*Arr_N-(LabBase+(LabExpOn)*LabExpAdd))))/(Arr_M+Arr_E+Arr_N) -> 0.9962963 | D6: =(MAX(0,((CEILING((0.8)*(Arr_M*(1+0.5*Acuity_M))/Cap_Doc,1)+CEILING((0.8)*(Arr_E*(1+0.5*Acuity_E))/Cap_Doc,1)+CEILING((0.8)*(Arr_N*(1+0.5*Acuity_N))/Cap_Doc,1)))-Avail_Doc-(OTCapPct)*MIN((CEILING((0.8)*(Arr_M*(1+0.5*Acuity_M))/Cap_Doc,1)+CEILING((0.8)*(Arr_E*(1+0.5*Acuity_E))/Cap_Doc,1)+CEILING((0.8)*(Arr_N*(1+0.5*Acuity_N))/Cap_Doc,1)),Avail_Doc)))*Cap_Doc+(MAX(0,((CEILING((0.8)*(Arr_M)/Cap_Nurse,1)+CEILING((0.8)*(Arr_E)/Cap_Nurse,1)+CEILING((0.8)*(Arr_N)/Cap_Nurse,1)))-Avail_Nurse-(OTCapPct)*MIN((CEILING((0.8)*(Arr_M)/Cap_Nurse,1)+CEILING((0.8)*(Arr_E)/Cap_Nurse,1)+CEILING((0.8)*(Arr_N)/Cap_Nurse,1)),Avail_Nurse)))*Cap_Nurse+(MAX(0,((CEILING((0.8)*(Arr_M)/Cap_Tech,1)+CEILING((0.8)*(Arr_E)/Cap_Tech,1)+CEILING((0.8)*(Arr_N)/Cap_Tech,1)))-Avail_Tech-(OTCapPct)*MIN((CEILING((0.8)*(Arr_M)/Cap_Tech,1)+CEILING((0.8)*(Arr_E)/Cap_Tech,1)+CEILING((0.8)*(Arr_N)/Cap_Tech,1)),Avail_Tech)))*Cap_Tech+(MAX(0,(0.8)*Arr_M-(BedsAdded+BedsCurrent)*ShiftHours/BedHr_M)+MAX(0,(0.8)*Arr_E-(BedsAdded+BedsCurrent)*ShiftHours/BedHr_E)+MAX(0,(0.8)*Arr_N-(BedsAdded+BedsCurrent)*ShiftHours/BedHr_N))+(MAX(0,(0.8)*Arr_M*Acuity_M-(ImgBase+(ImgExpOn)*ImgExpAdd))+MAX(0,(0.8)*Arr_E*Acuity_E-(ImgBase+(ImgExpOn)*ImgExpAdd))+MAX(0,(0.8)*Arr_N*Acuity_N-(ImgBase+(ImgExpOn)*ImgExpAdd)))+(MAX(0,(0.8)*Arr_M-(LabBase+(LabExpOn)*LabExpAdd))+MAX(0,(0.8)*Arr_E-(LabBase+(LabExpOn)*LabExpAdd))+MAX(0,(0.8)*Arr_N-(LabBase+(LabExpOn)*LabExpAdd))) -> 1 | E6: =B6-B11 -> -198560
A7: 0.85 | B7: =((MIN((CEILING((0.85)*(Arr_M*(1+0.5*Acuity_M))/Cap_Doc,1)+CEILING((0.85)*(Arr_E*(1+0.5*Acuity_E))/Cap_Doc,1)+CEILING((0.85)*(Arr_N*(1+0.5*Acuity_N))/Cap_Doc,1)),Avail_Doc))*RegCost_Doc+(MIN(MAX((CEILING((0.85)*(Arr_M*(1+0.5*Acuity_M))/Cap_Doc,1)+CEILING((0.85)*(Arr_E*(1+0.5*Acuity_E))/Cap_Doc,1)+CEILING((0.85)*(Arr_N*(1+0.5*Acuity_N))/Cap_Doc,1))-Avail_Doc,0),(OTCapPct)*MIN((CEILING((0.85)*(Arr_M*(1+0.5*Acuity_M))/Cap_Doc,1)+CEILING((0.85)*(Arr_E*(1+0.5*Acuity_E))/Cap_Doc,1)+CEILING((0.85)*(Arr_N*(1+0.5*Acuity_N))/Cap_Doc,1)),Avail_Doc)))*OTCost_Doc+(MIN((CEILING((0.85)*(Arr_M)/Cap_Nurse,1)+CEILING((0.85)*(Arr_E)/Cap_Nurse,1)+CEILING((0.85)*(Arr_N)/Cap_Nurse,1)),Avail_Nurse))*RegCost_Nurse+(MIN(MAX((CEILING((0.85)*(Arr_M)/Cap_Nurse,1)+CEILING((0.85)*(Arr_E)/Cap_Nurse,1)+CEILING((0.85)*(Arr_N)/Cap_Nurse,1))-Avail_Nurse,0),(OTCapPct)*MIN((CEILING((0.85)*(Arr_M)/Cap_Nurse,1)+CEILING((0.85)*(Arr_E)/Cap_Nurse,1)+CEILING((0.85)*(Arr_N)/Cap_Nurse,1)),Avail_Nurse)))*OTCost_Nurse+(MIN((CEILING((0.85)*(Arr_M)/Cap_Tech,1)+CEILING((0.85)*(Arr_E)/Cap_Tech,1)+CEILING((0.85)*(Arr_N)/Cap_Tech,1)),Avail_Tech))*RegCost_Tech+(MIN(MAX((CEILING((0.85)*(Arr_M)/Cap_Tech,1)+CEILING((0.85)*(Arr_E)/Cap_Tech,1)+CEILING((0.85)*(Arr_N)/Cap_Tech,1))-Avail_Tech,0),(OTCapPct)*MIN((CEILING((0.85)*(Arr_M)/Cap_Tech,1)+CEILING((0.85)*(Arr_E)/Cap_Tech,1)+CEILING((0.85)*(Arr_N)/Cap_Tech,1)),Avail_Tech)))*OTCost_Tech)+((BedsAdded)*BedCostPerBed+(ImgExpOn)*ImgExpCost+(LabExpOn)*LabExpCost)+(((MAX(0,((CEILING((0.85)*(Arr_M*(1+0.5*Acuity_M))/Cap_Doc,1)+CEILING((0.85)*(Arr_E*(1+0.5*Acuity_E))/Cap_Doc,1)+CEILING((0.85)*(Arr_N*(1+0.5*Acuity_N))/Cap_Doc,1)))-Avail_Doc-(OTCapPct)*MIN((CEILING((0.85)*(Arr_M*(1+0.5*Acuity_M))/Cap_Doc,1)+CEILING((0.85)*(Arr_E*(1+0.5*Acuity_E))/Cap_Doc,1)+CEILING((0.85)*(Arr_N*(1+0.5*Acuity_N))/Cap_Doc,1)),Avail_Doc)))*Cap_Doc+(MAX(0,((CEILING((0.85)*(Arr_M)/Cap_Nurse,1)+CEILING((0.85)*(Arr_E)/Cap_Nurse,1)+CEILING((0.85)*(Arr_N)/Cap_Nurse,1)))-Avail_Nurse-(OTCapPct)*MIN((CEILING((0.85)*(Arr_M)/Cap_Nurse,1)+CEILING((0.85)*(Arr_E)/Cap_Nurse,1)+CEILING((0.85)*(Arr_N)/Cap_Nurse,1)),Avail_Nurse)))*Cap_Nurse+(MAX(0,((CEILING((0.85)*(Arr_M)/Cap_Tech,1)+CEILING((0.85)*(Arr_E)/Cap_Tech,1)+CEILING((0.85)*(Arr_N)/Cap_Tech,1)))-Avail_Tech-(OTCapPct)*MIN((CEILING((0.85)*(Arr_M)/Cap_Tech,1)+CEILING((0.85)*(Arr_E)/Cap_Tech,1)+CEILING((0.85)*(Arr_N)/Cap_Tech,1)),Avail_Tech)))*Cap_Tech+(MAX(0,(0.85)*Arr_M-(BedsAdded+BedsCurrent)*ShiftHours/BedHr_M)+MAX(0,(0.85)*Arr_E-(BedsAdded+BedsCurrent)*ShiftHours/BedHr_E)+MAX(0,(0.85)*Arr_N-(BedsAdded+BedsCurrent)*ShiftHours/BedHr_N))+(MAX(0,(0.85)*Arr_M*Acuity_M-(ImgBase+(ImgExpOn)*ImgExpAdd))+MAX(0,(0.85)*Arr_E*Acuity_E-(ImgBase+(ImgExpOn)*ImgExpAdd))+MAX(0,(0.85)*Arr_N*Acuity_N-(ImgBase+(ImgExpOn)*ImgExpAdd)))+(MAX(0,(0.85)*Arr_M-(LabBase+(LabExpOn)*LabExpAdd))+MAX(0,(0.85)*Arr_E-(LabBase+(LabExpOn)*LabExpAdd))+MAX(0,(0.85)*Arr_N-(LabBase+(LabExpOn)*LabExpAdd))))*(PenUncovered*(1-DivertShare)+PenDiverted*DivertShare)) -> 319350 | C7: =1-((MAX(0,((CEILING((0.85)*(Arr_M*(1+0.5*Acuity_M))/Cap_Doc,1)+CEILING((0.85)*(Arr_E*(1+0.5*Acuity_E))/Cap_Doc,1)+CEILING((0.85)*(Arr_N*(1+0.5*Acuity_N))/Cap_Doc,1)))-Avail_Doc-(OTCapPct)*MIN((CEILING((0.85)*(Arr_M*(1+0.5*Acuity_M))/Cap_Doc,1)+CEILING((0.85)*(Arr_E*(1+0.5*Acuity_E))/Cap_Doc,1)+CEILING((0.85)*(Arr_N*(1+0.5*Acuity_N))/Cap_Doc,1)),Avail_Doc)))*Cap_Doc+(MAX(0,((CEILING((0.85)*(Arr_M)/Cap_Nurse,1)+CEILING((0.85)*(Arr_E)/Cap_Nurse,1)+CEILING((0.85)*(Arr_N)/Cap_Nurse,1)))-Avail_Nurse-(OTCapPct)*MIN((CEILING((0.85)*(Arr_M)/Cap_Nurse,1)+CEILING((0.85)*(Arr_E)/Cap_Nurse,1)+CEILING((0.85)*(Arr_N)/Cap_Nurse,1)),Avail_Nurse)))*Cap_Nurse+(MAX(0,((CEILING((0.85)*(Arr_M)/Cap_Tech,1)+CEILING((0.85)*(Arr_E)/Cap_Tech,1)+CEILING((0.85)*(Arr_N)/Cap_Tech,1)))-Avail_Tech-(OTCapPct)*MIN((CEILING((0.85)*(Arr_M)/Cap_Tech,1)+CEILING((0.85)*(Arr_E)/Cap_Tech,1)+CEILING((0.85)*(Arr_N)/Cap_Tech,1)),Avail_Tech)))*Cap_Tech+(MAX(0,(0.85)*Arr_M-(BedsAdded+BedsCurrent)*ShiftHours/BedHr_M)+MAX(0,(0.85)*Arr_E-(BedsAdded+BedsCurrent)*ShiftHours/BedHr_E)+MAX(0,(0.85)*Arr_N-(BedsAdded+BedsCurrent)*ShiftHours/BedHr_N))+(MAX(0,(0.85)*Arr_M*Acuity_M-(ImgBase+(ImgExpOn)*ImgExpAdd))+MAX(0,(0.85)*Arr_E*Acuity_E-(ImgBase+(ImgExpOn)*ImgExpAdd))+MAX(0,(0.85)*Arr_N*Acuity_N-(ImgBase+(ImgExpOn)*ImgExpAdd)))+(MAX(0,(0.85)*Arr_M-(LabBase+(LabExpOn)*LabExpAdd))+MAX(0,(0.85)*Arr_E-(LabBase+(LabExpOn)*LabExpAdd))+MAX(0,(0.85)*Arr_N-(LabBase+(LabExpOn)*LabExpAdd))))/(Arr_M+Arr_E+Arr_N) -> 0.97407407 | D7: =(MAX(0,((CEILING((0.85)*(Arr_M*(1+0.5*Acuity_M))/Cap_Doc,1)+CEILING((0.85)*(Arr_E*(1+0.5*Acuity_E))/Cap_Doc,1)+CEILING((0.85)*(Arr_N*(1+0.5*Acuity_N))/Cap_Doc,1)))-Avail_Doc-(OTCapPct)*MIN((CEILING((0.85)*(Arr_M*(1+0.5*Acuity_M))/Cap_Doc,1)+CEILING((0.85)*(Arr_E*(1+0.5*Acuity_E))/Cap_Doc,1)+CEILING((0.85)*(Arr_N*(1+0.5*Acuity_N))/Cap_Doc,1)),Avail_Doc)))*Cap_Doc+(MAX(0,((CEILING((0.85)*(Arr_M)/Cap_Nurse,1)+CEILING((0.85)*(Arr_E)/Cap_Nurse,1)+CEILING((0.85)*(Arr_N)/Cap_Nurse,1)))-Avail_Nurse-(OTCapPct)*MIN((CEILING((0.85)*(Arr_M)/Cap_Nurse,1)+CEILING((0.85)*(Arr_E)/Cap_Nurse,1)+CEILING((0.85)*(Arr_N)/Cap_Nurse,1)),Avail_Nurse)))*Cap_Nurse+(MAX(0,((CEILING((0.85)*(Arr_M)/Cap_Tech,1)+CEILING((0.85)*(Arr_E)/Cap_Tech,1)+CEILING((0.85)*(Arr_N)/Cap_Tech,1)))-Avail_Tech-(OTCapPct)*MIN((CEILING((0.85)*(Arr_M)/Cap_Tech,1)+CEILING((0.85)*(Arr_E)/Cap_Tech,1)+CEILING((0.85)*(Arr_N)/Cap_Tech,1)),Avail_Tech)))*Cap_Tech+(MAX(0,(0.85)*Arr_M-(BedsAdded+BedsCurrent)*ShiftHours/BedHr_M)+MAX(0,(0.85)*Arr_E-(BedsAdded+BedsCurrent)*ShiftHours/BedHr_E)+MAX(0,(0.85)*Arr_N-(BedsAdded+BedsCurrent)*ShiftHours/BedHr_N))+(MAX(0,(0.85)*Arr_M*Acuity_M-(ImgBase+(ImgExpOn)*ImgExpAdd))+MAX(0,(0.85)*Arr_E*Acuity_E-(ImgBase+(ImgExpOn)*ImgExpAdd))+MAX(0,(0.85)*Arr_N*Acuity_N-(ImgBase+(ImgExpOn)*ImgExpAdd)))+(MAX(0,(0.85)*Arr_M-(LabBase+(LabExpOn)*LabExpAdd))+MAX(0,(0.85)*Arr_E-(LabBase+(LabExpOn)*LabExpAdd))+MAX(0,(0.85)*Arr_N-(LabBase+(LabExpOn)*LabExpAdd))) -> 7 | E7: =B7-B11 -> -147260
A8: 0.9 | B8: =((MIN((CEILING((0.9)*(Arr_M*(1+0.5*Acuity_M))/Cap_Doc,1)+CEILING((0.9)*(Arr_E*(1+0.5*Acuity_E))/Cap_Doc,1)+CEILING((0.9)*(Arr_N*(1+0.5*Acuity_N))/Cap_Doc,1)),Avail_Doc))*RegCost_Doc+(MIN(MAX((CEILING((0.9)*(Arr_M*(1+0.5*Acuity_M))/Cap_Doc,1)+CEILING((0.9)*(Arr_E*(1+0.5*Acuity_E))/Cap_Doc,1)+CEILING((0.9)*(Arr_N*(1+0.5*Acuity_N))/Cap_Doc,1))-Avail_Doc,0),(OTCapPct)*MIN((CEILING((0.9)*(Arr_M*(1+0.5*Acuity_M))/Cap_Doc,1)+CEILING((0.9)*(Arr_E*(1+0.5*Acuity_E))/Cap_Doc,1)+CEILING((0.9)*(Arr_N*(1+0.5*Acuity_N))/Cap_Doc,1)),Avail_Doc)))*OTCost_Doc+(MIN((CEILING((0.9)*(Arr_M)/Cap_Nurse,1)+CEILING((0.9)*(Arr_E)/Cap_Nurse,1)+CEILING((0.9)*(Arr_N)/Cap_Nurse,1)),Avail_Nurse))*RegCost_Nurse+(MIN(MAX((CEILING((0.9)*(Arr_M)/Cap_Nurse,1)+CEILING((0.9)*(Arr_E)/Cap_Nurse,1)+CEILING((0.9)*(Arr_N)/Cap_Nurse,1))-Avail_Nurse,0),(OTCapPct)*MIN((CEILING((0.9)*(Arr_M)/Cap_Nurse,1)+CEILING((0.9)*(Arr_E)/Cap_Nurse,1)+CEILING((0.9)*(Arr_N)/Cap_Nurse,1)),Avail_Nurse)))*OTCost_Nurse+(MIN((CEILING((0.9)*(Arr_M)/Cap_Tech,1)+CEILING((0.9)*(Arr_E)/Cap_Tech,1)+CEILING((0.9)*(Arr_N)/Cap_Tech,1)),Avail_Tech))*RegCost_Tech+(MIN(MAX((CEILING((0.9)*(Arr_M)/Cap_Tech,1)+CEILING((0.9)*(Arr_E)/Cap_Tech,1)+CEILING((0.9)*(Arr_N)/Cap_Tech,1))-Avail_Tech,0),(OTCapPct)*MIN((CEILING((0.9)*(Arr_M)/Cap_Tech,1)+CEILING((0.9)*(Arr_E)/Cap_Tech,1)+CEILING((0.9)*(Arr_N)/Cap_Tech,1)),Avail_Tech)))*OTCost_Tech)+((BedsAdded)*BedCostPerBed+(ImgExpOn)*ImgExpCost+(LabExpOn)*LabExpCost)+(((MAX(0,((CEILING((0.9)*(Arr_M*(1+0.5*Acuity_M))/Cap_Doc,1)+CEILING((0.9)*(Arr_E*(1+0.5*Acuity_E))/Cap_Doc,1)+CEILING((0.9)*(Arr_N*(1+0.5*Acuity_N))/Cap_Doc,1)))-Avail_Doc-(OTCapPct)*MIN((CEILING((0.9)*(Arr_M*(1+0.5*Acuity_M))/Cap_Doc,1)+CEILING((0.9)*(Arr_E*(1+0.5*Acuity_E))/Cap_Doc,1)+CEILING((0.9)*(Arr_N*(1+0.5*Acuity_N))/Cap_Doc,1)),Avail_Doc)))*Cap_Doc+(MAX(0,((CEILING((0.9)*(Arr_M)/Cap_Nurse,1)+CEILING((0.9)*(Arr_E)/Cap_Nurse,1)+CEILING((0.9)*(Arr_N)/Cap_Nurse,1)))-Avail_Nurse-(OTCapPct)*MIN((CEILING((0.9)*(Arr_M)/Cap_Nurse,1)+CEILING((0.9)*(Arr_E)/Cap_Nurse,1)+CEILING((0.9)*(Arr_N)/Cap_Nurse,1)),Avail_Nurse)))*Cap_Nurse+(MAX(0,((CEILING((0.9)*(Arr_M)/Cap_Tech,1)+CEILING((0.9)*(Arr_E)/Cap_Tech,1)+CEILING((0.9)*(Arr_N)/Cap_Tech,1)))-Avail_Tech-(OTCapPct)*MIN((CEILING((0.9)*(Arr_M)/Cap_Tech,1)+CEILING((0.9)*(Arr_E)/Cap_Tech,1)+CEILING((0.9)*(Arr_N)/Cap_Tech,1)),Avail_Tech)))*Cap_Tech+(MAX(0,(0.9)*Arr_M-(BedsAdded+BedsCurrent)*ShiftHours/BedHr_M)+MAX(0,(0.9)*Arr_E-(BedsAdded+BedsCurrent)*ShiftHours/BedHr_E)+MAX(0,(0.9)*Arr_N-(BedsAdded+BedsCurrent)*ShiftHours/BedHr_N))+(MAX(0,(0.9)*Arr_M*Acuity_M-(ImgBase+(ImgExpOn)*ImgExpAdd))+MAX(0,(0.9)*Arr_E*Acuity_E-(ImgBase+(ImgExpOn)*ImgExpAdd))+MAX(0,(0.9)*Arr_N*Acuity_N-(ImgBase+(ImgExpOn)*ImgExpAdd)))+(MAX(0,(0.9)*Arr_M-(LabBase+(LabExpOn)*LabExpAdd))+MAX(0,(0.9)*Arr_E-(LabBase+(LabExpOn)*LabExpAdd))+MAX(0,(0.9)*Arr_N-(LabBase+(LabExpOn)*LabExpAdd))))*(PenUncovered*(1-DivertShare)+PenDiverted*DivertShare)) -> 361650 | C8: =1-((MAX(0,((CEILING((0.9)*(Arr_M*(1+0.5*Acuity_M))/Cap_Doc,1)+CEILING((0.9)*(Arr_E*(1+0.5*Acuity_E))/Cap_Doc,1)+CEILING((0.9)*(Arr_N*(1+0.5*Acuity_N))/Cap_Doc,1)))-Avail_Doc-(OTCapPct)*MIN((CEILING((0.9)*(Arr_M*(1+0.5*Acuity_M))/Cap_Doc,1)+CEILING((0.9)*(Arr_E*(1+0.5*Acuity_E))/Cap_Doc,1)+CEILING((0.9)*(Arr_N*(1+0.5*Acuity_N))/Cap_Doc,1)),Avail_Doc)))*Cap_Doc+(MAX(0,((CEILING((0.9)*(Arr_M)/Cap_Nurse,1)+CEILING((0.9)*(Arr_E)/Cap_Nurse,1)+CEILING((0.9)*(Arr_N)/Cap_Nurse,1)))-Avail_Nurse-(OTCapPct)*MIN((CEILING((0.9)*(Arr_M)/Cap_Nurse,1)+CEILING((0.9)*(Arr_E)/Cap_Nurse,1)+CEILING((0.9)*(Arr_N)/Cap_Nurse,1)),Avail_Nurse)))*Cap_Nurse+(MAX(0,((CEILING((0.9)*(Arr_M)/Cap_Tech,1)+CEILING((0.9)*(Arr_E)/Cap_Tech,1)+CEILING((0.9)*(Arr_N)/Cap_Tech,1)))-Avail_Tech-(OTCapPct)*MIN((CEILING((0.9)*(Arr_M)/Cap_Tech,1)+CEILING((0.9)*(Arr_E)/Cap_Tech,1)+CEILING((0.9)*(Arr_N)/Cap_Tech,1)),Avail_Tech)))*Cap_Tech+(MAX(0,(0.9)*Arr_M-(BedsAdded+BedsCurrent)*ShiftHours/BedHr_M)+MAX(0,(0.9)*Arr_E-(BedsAdded+BedsCurrent)*ShiftHours/BedHr_E)+MAX(0,(0.9)*Arr_N-(BedsAdded+BedsCurrent)*ShiftHours/BedHr_N))+(MAX(0,(0.9)*Arr_M*Acuity_M-(ImgBase+(ImgExpOn)*ImgExpAdd))+MAX(0,(0.9)*Arr_E*Acuity_E-(ImgBase+(ImgExpOn)*ImgExpAdd))+MAX(0,(0.9)*Arr_N*Acuity_N-(ImgBase+(ImgExpOn)*ImgExpAdd)))+(MAX(0,(0.9)*Arr_M-(LabBase+(LabExpOn)*LabExpAdd))+MAX(0,(0.9)*Arr_E-(LabBase+(LabExpOn)*LabExpAdd))+MAX(0,(0.9)*Arr_N-(LabBase+(LabExpOn)*LabExpAdd))))/(Arr_M+Arr_E+Arr_N) -> 0.95185185 | D8: =(MAX(0,((CEILING((0.9)*(Arr_M*(1+0.5*Acuity_M))/Cap_Doc,1)+CEILING((0.9)*(Arr_E*(1+0.5*Acuity_E))/Cap_Doc,1)+CEILING((0.9)*(Arr_N*(1+0.5*Acuity_N))/Cap_Doc,1)))-Avail_Doc-(OTCapPct)*MIN((CEILING((0.9)*(Arr_M*(1+0.5*Acuity_M))/Cap_Doc,1)+CEILING((0.9)*(Arr_E*(1+0.5*Acuity_E))/Cap_Doc,1)+CEILING((0.9)*(Arr_N*(1+0.5*Acuity_N))/Cap_Doc,1)),Avail_Doc)))*Cap_Doc+(MAX(0,((CEILING((0.9)*(Arr_M)/Cap_Nurse,1)+CEILING((0.9)*(Arr_E)/Cap_Nurse,1)+CEILING((0.9)*(Arr_N)/Cap_Nurse,1)))-Avail_Nurse-(OTCapPct)*MIN((CEILING((0.9)*(Arr_M)/Cap_Nurse,1)+CEILING((0.9)*(Arr_E)/Cap_Nurse,1)+CEILING((0.9)*(Arr_N)/Cap_Nurse,1)),Avail_Nurse)))*Cap_Nurse+(MAX(0,((CEILING((0.9)*(Arr_M)/Cap_Tech,1)+CEILING((0.9)*(Arr_E)/Cap_Tech,1)+CEILING((0.9)*(Arr_N)/Cap_Tech,1)))-Avail_Tech-(OTCapPct)*MIN((CEILING((0.9)*(Arr_M)/Cap_Tech,1)+CEILING((0.9)*(Arr_E)/Cap_Tech,1)+CEILING((0.9)*(Arr_N)/Cap_Tech,1)),Avail_Tech)))*Cap_Tech+(MAX(0,(0.9)*Arr_M-(BedsAdded+BedsCurrent)*ShiftHours/BedHr_M)+MAX(0,(0.9)*Arr_E-(BedsAdded+BedsCurrent)*ShiftHours/BedHr_E)+MAX(0,(0.9)*Arr_N-(BedsAdded+BedsCurrent)*ShiftHours/BedHr_N))+(MAX(0,(0.9)*Arr_M*Acuity_M-(ImgBase+(ImgExpOn)*ImgExpAdd))+MAX(0,(0.9)*Arr_E*Acuity_E-(ImgBase+(ImgExpOn)*ImgExpAdd))+MAX(0,(0.9)*Arr_N*Acuity_N-(ImgBase+(ImgExpOn)*ImgExpAdd)))+(MAX(0,(0.9)*Arr_M-(LabBase+(LabExpOn)*LabExpAdd))+MAX(0,(0.9)*Arr_E-(LabBase+(LabExpOn)*LabExpAdd))+MAX(0,(0.9)*Arr_N-(LabBase+(LabExpOn)*LabExpAdd))) -> 13 | E8: =B8-B11 -> -104960
A9: 0.95 | B9: =((MIN((CEILING((0.95)*(Arr_M*(1+0.5*Acuity_M))/Cap_Doc,1)+CEILING((0.95)*(Arr_E*(1+0.5*Acuity_E))/Cap_Doc,1)+CEILING((0.95)*(Arr_N*(1+0.5*Acuity_N))/Cap_Doc,1)),Avail_Doc))*RegCost_Doc+(MIN(MAX((CEILING((0.95)*(Arr_M*(1+0.5*Acuity_M))/Cap_Doc,1)+CEILING((0.95)*(Arr_E*(1+0.5*Acuity_E))/Cap_Doc,1)+CEILING((0.95)*(Arr_N*(1+0.5*Acuity_N))/Cap_Doc,1))-Avail_Doc,0),(OTCapPct)*MIN((CEILING((0.95)*(Arr_M*(1+0.5*Acuity_M))/Cap_Doc,1)+CEILING((0.95)*(Arr_E*(1+0.5*Acuity_E))/Cap_Doc,1)+CEILING((0.95)*(Arr_N*(1+0.5*Acuity_N))/Cap_Doc,1)),Avail_Doc)))*OTCost_Doc+(MIN((CEILING((0.95)*(Arr_M)/Cap_Nurse,1)+CEILING((0.95)*(Arr_E)/Cap_Nurse,1)+CEILING((0.95)*(Arr_N)/Cap_Nurse,1)),Avail_Nurse))*RegCost_Nurse+(MIN(MAX((CEILING((0.95)*(Arr_M)/Cap_Nurse,1)+CEILING((0.95)*(Arr_E)/Cap_Nurse,1)+CEILING((0.95)*(Arr_N)/Cap_Nurse,1))-Avail_Nurse,0),(OTCapPct)*MIN((CEILING((0.95)*(Arr_M)/Cap_Nurse,1)+CEILING((0.95)*(Arr_E)/Cap_Nurse,1)+CEILING((0.95)*(Arr_N)/Cap_Nurse,1)),Avail_Nurse)))*OTCost_Nurse+(MIN((CEILING((0.95)*(Arr_M)/Cap_Tech,1)+CEILING((0.95)*(Arr_E)/Cap_Tech,1)+CEILING((0.95)*(Arr_N)/Cap_Tech,1)),Avail_Tech))*RegCost_Tech+(MIN(MAX((CEILING((0.95)*(Arr_M)/Cap_Tech,1)+CEILING((0.95)*(Arr_E)/Cap_Tech,1)+CEILING((0.95)*(Arr_N)/Cap_Tech,1))-Avail_Tech,0),(OTCapPct)*MIN((CEILING((0.95)*(Arr_M)/Cap_Tech,1)+CEILING((0.95)*(Arr_E)/Cap_Tech,1)+CEILING((0.95)*(Arr_N)/Cap_Tech,1)),Avail_Tech)))*OTCost_Tech)+((BedsAdded)*BedCostPerBed+(ImgExpOn)*ImgExpCost+(LabExpOn)*LabExpCost)+(((MAX(0,((CEILING((0.95)*(Arr_M*(1+0.5*Acuity_M))/Cap_Doc,1)+CEILING((0.95)*(Arr_E*(1+0.5*Acuity_E))/Cap_Doc,1)+CEILING((0.95)*(Arr_N*(1+0.5*Acuity_N))/Cap_Doc,1)))-Avail_Doc-(OTCapPct)*MIN((CEILING((0.95)*(Arr_M*(1+0.5*Acuity_M))/Cap_Doc,1)+CEILING((0.95)*(Arr_E*(1+0.5*Acuity_E))/Cap_Doc,1)+CEILING((0.95)*(Arr_N*(1+0.5*Acuity_N))/Cap_Doc,1)),Avail_Doc)))*Cap_Doc+(MAX(0,((CEILING((0.95)*(Arr_M)/Cap_Nurse,1)+CEILING((0.95)*(Arr_E)/Cap_Nurse,1)+CEILING((0.95)*(Arr_N)/Cap_Nurse,1)))-Avail_Nurse-(OTCapPct)*MIN((CEILING((0.95)*(Arr_M)/Cap_Nurse,1)+CEILING((0.95)*(Arr_E)/Cap_Nurse,1)+CEILING((0.95)*(Arr_N)/Cap_Nurse,1)),Avail_Nurse)))*Cap_Nurse+(MAX(0,((CEILING((0.95)*(Arr_M)/Cap_Tech,1)+CEILING((0.95)*(Arr_E)/Cap_Tech,1)+CEILING((0.95)*(Arr_N)/Cap_Tech,1)))-Avail_Tech-(OTCapPct)*MIN((CEILING((0.95)*(Arr_M)/Cap_Tech,1)+CEILING((0.95)*(Arr_E)/Cap_Tech,1)+CEILING((0.95)*(Arr_N)/Cap_Tech,1)),Avail_Tech)))*Cap_Tech+(MAX(0,(0.95)*Arr_M-(BedsAdded+BedsCurrent)*ShiftHours/BedHr_M)+MAX(0,(0.95)*Arr_E-(BedsAdded+BedsCurrent)*ShiftHours/BedHr_E)+MAX(0,(0.95)*Arr_N-(BedsAdded+BedsCurrent)*ShiftHours/BedHr_N))+(MAX(0,(0.95)*Arr_M*Acuity_M-(ImgBase+(ImgExpOn)*ImgExpAdd))+MAX(0,(0.95)*Arr_E*Acuity_E-(ImgBase+(ImgExpOn)*ImgExpAdd))+MAX(0,(0.95)*Arr_N*Acuity_N-(ImgBase+(ImgExpOn)*ImgExpAdd)))+(MAX(0,(0.95)*Arr_M-(LabBase+(LabExpOn)*LabExpAdd))+MAX(0,(0.95)*Arr_E-(LabBase+(LabExpOn)*LabExpAdd))+MAX(0,(0.95)*Arr_N-(LabBase+(LabExpOn)*LabExpAdd))))*(PenUncovered*(1-DivertShare)+PenDiverted*DivertShare)) -> 466610 | C9: =1-((MAX(0,((CEILING((0.95)*(Arr_M*(1+0.5*Acuity_M))/Cap_Doc,1)+CEILING((0.95)*(Arr_E*(1+0.5*Acuity_E))/Cap_Doc,1)+CEILING((0.95)*(Arr_N*(1+0.5*Acuity_N))/Cap_Doc,1)))-Avail_Doc-(OTCapPct)*MIN((CEILING((0.95)*(Arr_M*(1+0.5*Acuity_M))/Cap_Doc,1)+CEILING((0.95)*(Arr_E*(1+0.5*Acuity_E))/Cap_Doc,1)+CEILING((0.95)*(Arr_N*(1+0.5*Acuity_N))/Cap_Doc,1)),Avail_Doc)))*Cap_Doc+(MAX(0,((CEILING((0.95)*(Arr_M)/Cap_Nurse,1)+CEILING((0.95)*(Arr_E)/Cap_Nurse,1)+CEILING((0.95)*(Arr_N)/Cap_Nurse,1)))-Avail_Nurse-(OTCapPct)*MIN((CEILING((0.95)*(Arr_M)/Cap_Nurse,1)+CEILING((0.95)*(Arr_E)/Cap_Nurse,1)+CEILING((0.95)*(Arr_N)/Cap_Nurse,1)),Avail_Nurse)))*Cap_Nurse+(MAX(0,((CEILING((0.95)*(Arr_M)/Cap_Tech,1)+CEILING((0.95)*(Arr_E)/Cap_Tech,1)+CEILING((0.95)*(Arr_N)/Cap_Tech,1)))-Avail_Tech-(OTCapPct)*MIN((CEILING((0.95)*(Arr_M)/Cap_Tech,1)+CEILING((0.95)*(Arr_E)/Cap_Tech,1)+CEILING((0.95)*(Arr_N)/Cap_Tech,1)),Avail_Tech)))*Cap_Tech+(MAX(0,(0.95)*Arr_M-(BedsAdded+BedsCurrent)*ShiftHours/BedHr_M)+MAX(0,(0.95)*Arr_E-(BedsAdded+BedsCurrent)*ShiftHours/BedHr_E)+MAX(0,(0.95)*Arr_N-(BedsAdded+BedsCurrent)*ShiftHours/BedHr_N))+(MAX(0,(0.95)*Arr_M*Acuity_M-(ImgBase+(ImgExpOn)*ImgExpAdd))+MAX(0,(0.95)*Arr_E*Acuity_E-(ImgBase+(ImgExpOn)*ImgExpAdd))+MAX(0,(0.95)*Arr_N*Acuity_N-(ImgBase+(ImgExpOn)*ImgExpAdd)))+(MAX(0,(0.95)*Arr_M-(LabBase+(LabExpOn)*LabExpAdd))+MAX(0,(0.95)*Arr_E-(LabBase+(LabExpOn)*LabExpAdd))+MAX(0,(0.95)*Arr_N-(LabBase+(LabExpOn)*LabExpAdd))))/(Arr_M+Arr_E+Arr_N) -> 0.91037037 | D9: =(MAX(0,((CEILING((0.95)*(Arr_M*(1+0.5*Acuity_M))/Cap_Doc,1)+CEILING((0.95)*(Arr_E*(1+0.5*Acuity_E))/Cap_Doc,1)+CEILING((0.95)*(Arr_N*(1+0.5*Acuity_N))/Cap_Doc,1)))-Avail_Doc-(OTCapPct)*MIN((CEILING((0.95)*(Arr_M*(1+0.5*Acuity_M))/Cap_Doc,1)+CEILING((0.95)*(Arr_E*(1+0.5*Acuity_E))/Cap_Doc,1)+CEILING((0.95)*(Arr_N*(1+0.5*Acuity_N))/Cap_Doc,1)),Avail_Doc)))*Cap_Doc+(MAX(0,((CEILING((0.95)*(Arr_M)/Cap_Nurse,1)+CEILING((0.95)*(Arr_E)/Cap_Nurse,1)+CEILING((0.95)*(Arr_N)/Cap_Nurse,1)))-Avail_Nurse-(OTCapPct)*MIN((CEILING((0.95)*(Arr_M)/Cap_Nurse,1)+CEILING((0.95)*(Arr_E)/Cap_Nurse,1)+CEILING((0.95)*(Arr_N)/Cap_Nurse,1)),Avail_Nurse)))*Cap_Nurse+(MAX(0,((CEILING((0.95)*(Arr_M)/Cap_Tech,1)+CEILING((0.95)*(Arr_E)/Cap_Tech,1)+CEILING((0.95)*(Arr_N)/Cap_Tech,1)))-Avail_Tech-(OTCapPct)*MIN((CEILING((0.95)*(Arr_M)/Cap_Tech,1)+CEILING((0.95)*(Arr_E)/Cap_Tech,1)+CEILING((0.95)*(Arr_N)/Cap_Tech,1)),Avail_Tech)))*Cap_Tech+(MAX(0,(0.95)*Arr_M-(BedsAdded+BedsCurrent)*ShiftHours/BedHr_M)+MAX(0,(0.95)*Arr_E-(BedsAdded+BedsCurrent)*ShiftHours/BedHr_E)+MAX(0,(0.95)*Arr_N-(BedsAdded+BedsCurrent)*ShiftHours/BedHr_N))+(MAX(0,(0.95)*Arr_M*Acuity_M-(ImgBase+(ImgExpOn)*ImgExpAdd))+MAX(0,(0.95)*Arr_E*Acuity_E-(ImgBase+(ImgExpOn)*ImgExpAdd))+MAX(0,(0.95)*Arr_N*Acuity_N-(ImgBase+(ImgExpOn)*ImgExpAdd)))+(MAX(0,(0.95)*Arr_M-(LabBase+(LabExpOn)*LabExpAdd))+MAX(0,(0.95)*Arr_E-(LabBase+(LabExpOn)*LabExpAdd))+MAX(0,(0.95)*Arr_N-(LabBase+(LabExpOn)*LabExpAdd))) -> 24.2 | E9: =B9-B11 -> 0
A10: 0.99 | B10: =((MIN((CEILING((0.99)*(Arr_M*(1+0.5*Acuity_M))/Cap_Doc,1)+CEILING((0.99)*(Arr_E*(1+0.5*Acuity_E))/Cap_Doc,1)+CEILING((0.99)*(Arr_N*(1+0.5*Acuity_N))/Cap_Doc,1)),Avail_Doc))*RegCost_Doc+(MIN(MAX((CEILING((0.99)*(Arr_M*(1+0.5*Acuity_M))/Cap_Doc,1)+CEILING((0.99)*(Arr_E*(1+0.5*Acuity_E))/Cap_Doc,1)+CEILING((0.99)*(Arr_N*(1+0.5*Acuity_N))/Cap_Doc,1))-Avail_Doc,0),(OTCapPct)*MIN((CEILING((0.99)*(Arr_M*(1+0.5*Acuity_M))/Cap_Doc,1)+CEILING((0.99)*(Arr_E*(1+0.5*Acuity_E))/Cap_Doc,1)+CEILING((0.99)*(Arr_N*(1+0.5*Acuity_N))/Cap_Doc,1)),Avail_Doc)))*OTCost_Doc+(MIN((CEILING((0.99)*(Arr_M)/Cap_Nurse,1)+CEILING((0.99)*(Arr_E)/Cap_Nurse,1)+CEILING((0.99)*(Arr_N)/Cap_Nurse,1)),Avail_Nurse))*RegCost_Nurse+(MIN(MAX((CEILING((0.99)*(Arr_M)/Cap_Nurse,1)+CEILING((0.99)*(Arr_E)/Cap_Nurse,1)+CEILING((0.99)*(Arr_N)/Cap_Nurse,1))-Avail_Nurse,0),(OTCapPct)*MIN((CEILING((0.99)*(Arr_M)/Cap_Nurse,1)+CEILING((0.99)*(Arr_E)/Cap_Nurse,1)+CEILING((0.99)*(Arr_N)/Cap_Nurse,1)),Avail_Nurse)))*OTCost_Nurse+(MIN((CEILING((0.99)*(Arr_M)/Cap_Tech,1)+CEILING((0.99)*(Arr_E)/Cap_Tech,1)+CEILING((0.99)*(Arr_N)/Cap_Tech,1)),Avail_Tech))*RegCost_Tech+(MIN(MAX((CEILING((0.99)*(Arr_M)/Cap_Tech,1)+CEILING((0.99)*(Arr_E)/Cap_Tech,1)+CEILING((0.99)*(Arr_N)/Cap_Tech,1))-Avail_Tech,0),(OTCapPct)*MIN((CEILING((0.99)*(Arr_M)/Cap_Tech,1)+CEILING((0.99)*(Arr_E)/Cap_Tech,1)+CEILING((0.99)*(Arr_N)/Cap_Tech,1)),Avail_Tech)))*OTCost_Tech)+((BedsAdded)*BedCostPerBed+(ImgExpOn)*ImgExpCost+(LabExpOn)*LabExpCost)+(((MAX(0,((CEILING((0.99)*(Arr_M*(1+0.5*Acuity_M))/Cap_Doc,1)+CEILING((0.99)*(Arr_E*(1+0.5*Acuity_E))/Cap_Doc,1)+CEILING((0.99)*(Arr_N*(1+0.5*Acuity_N))/Cap_Doc,1)))-Avail_Doc-(OTCapPct)*MIN((CEILING((0.99)*(Arr_M*(1+0.5*Acuity_M))/Cap_Doc,1)+CEILING((0.99)*(Arr_E*(1+0.5*Acuity_E))/Cap_Doc,1)+CEILING((0.99)*(Arr_N*(1+0.5*Acuity_N))/Cap_Doc,1)),Avail_Doc)))*Cap_Doc+(MAX(0,((CEILING((0.99)*(Arr_M)/Cap_Nurse,1)+CEILING((0.99)*(Arr_E)/Cap_Nurse,1)+CEILING((0.99)*(Arr_N)/Cap_Nurse,1)))-Avail_Nurse-(OTCapPct)*MIN((CEILING((0.99)*(Arr_M)/Cap_Nurse,1)+CEILING((0.99)*(Arr_E)/Cap_Nurse,1)+CEILING((0.99)*(Arr_N)/Cap_Nurse,1)),Avail_Nurse)))*Cap_Nurse+(MAX(0,((CEILING((0.99)*(Arr_M)/Cap_Tech,1)+CEILING((0.99)*(Arr_E)/Cap_Tech,1)+CEILING((0.99)*(Arr_N)/Cap_Tech,1)))-Avail_Tech-(OTCapPct)*MIN((CEILING((0.99)*(Arr_M)/Cap_Tech,1)+CEILING((0.99)*(Arr_E)/Cap_Tech,1)+CEILING((0.99)*(Arr_N)/Cap_Tech,1)),Avail_Tech)))*Cap_Tech+(MAX(0,(0.99)*Arr_M-(BedsAdded+BedsCurrent)*ShiftHours/BedHr_M)+MAX(0,(0.99)*Arr_E-(BedsAdded+BedsCurrent)*ShiftHours/BedHr_E)+MAX(0,(0.99)*Arr_N-(BedsAdded+BedsCurrent)*ShiftHours/BedHr_N))+(MAX(0,(0.99)*Arr_M*Acuity_M-(ImgBase+(ImgExpOn)*ImgExpAdd))+MAX(0,(0.99)*Arr_E*Acuity_E-(ImgBase+(ImgExpOn)*ImgExpAdd))+MAX(0,(0.99)*Arr_N*Acuity_N-(ImgBase+(ImgExpOn)*ImgExpAdd)))+(MAX(0,(0.99)*Arr_M-(LabBase+(LabExpOn)*LabExpAdd))+MAX(0,(0.99)*Arr_E-(LabBase+(LabExpOn)*LabExpAdd))+MAX(0,(0.99)*Arr_N-(LabBase+(LabExpOn)*LabExpAdd))))*(PenUncovered*(1-DivertShare)+PenDiverted*DivertShare)) -> 565790 | C10: =1-((MAX(0,((CEILING((0.99)*(Arr_M*(1+0.5*Acuity_M))/Cap_Doc,1)+CEILING((0.99)*(Arr_E*(1+0.5*Acuity_E))/Cap_Doc,1)+CEILING((0.99)*(Arr_N*(1+0.5*Acuity_N))/Cap_Doc,1)))-Avail_Doc-(OTCapPct)*MIN((CEILING((0.99)*(Arr_M*(1+0.5*Acuity_M))/Cap_Doc,1)+CEILING((0.99)*(Arr_E*(1+0.5*Acuity_E))/Cap_Doc,1)+CEILING((0.99)*(Arr_N*(1+0.5*Acuity_N))/Cap_Doc,1)),Avail_Doc)))*Cap_Doc+(MAX(0,((CEILING((0.99)*(Arr_M)/Cap_Nurse,1)+CEILING((0.99)*(Arr_E)/Cap_Nurse,1)+CEILING((0.99)*(Arr_N)/Cap_Nurse,1)))-Avail_Nurse-(OTCapPct)*MIN((CEILING((0.99)*(Arr_M)/Cap_Nurse,1)+CEILING((0.99)*(Arr_E)/Cap_Nurse,1)+CEILING((0.99)*(Arr_N)/Cap_Nurse,1)),Avail_Nurse)))*Cap_Nurse+(MAX(0,((CEILING((0.99)*(Arr_M)/Cap_Tech,1)+CEILING((0.99)*(Arr_E)/Cap_Tech,1)+CEILING((0.99)*(Arr_N)/Cap_Tech,1)))-Avail_Tech-(OTCapPct)*MIN((CEILING((0.99)*(Arr_M)/Cap_Tech,1)+CEILING((0.99)*(Arr_E)/Cap_Tech,1)+CEILING((0.99)*(Arr_N)/Cap_Tech,1)),Avail_Tech)))*Cap_Tech+(MAX(0,(0.99)*Arr_M-(BedsAdded+BedsCurrent)*ShiftHours/BedHr_M)+MAX(0,(0.99)*Arr_E-(BedsAdded+BedsCurrent)*ShiftHours/BedHr_E)+MAX(0,(0.99)*Arr_N-(BedsAdded+BedsCurrent)*ShiftHours/BedHr_N))+(MAX(0,(0.99)*Arr_M*Acuity_M-(ImgBase+(ImgExpOn)*ImgExpAdd))+MAX(0,(0.99)*Arr_E*Acuity_E-(ImgBase+(ImgExpOn)*ImgExpAdd))+MAX(0,(0.99)*Arr_N*Acuity_N-(ImgBase+(ImgExpOn)*ImgExpAdd)))+(MAX(0,(0.99)*Arr_M-(LabBase+(LabExpOn)*LabExpAdd))+MAX(0,(0.99)*Arr_E-(LabBase+(LabExpOn)*LabExpAdd))+MAX(0,(0.99)*Arr_N-(LabBase+(LabExpOn)*LabExpAdd))))/(Arr_M+Arr_E+Arr_N) -> 0.87481481 | D10: =(MAX(0,((CEILING((0.99)*(Arr_M*(1+0.5*Acuity_M))/Cap_Doc,1)+CEILING((0.99)*(Arr_E*(1+0.5*Acuity_E))/Cap_Doc,1)+CEILING((0.99)*(Arr_N*(1+0.5*Acuity_N))/Cap_Doc,1)))-Avail_Doc-(OTCapPct)*MIN((CEILING((0.99)*(Arr_M*(1+0.5*Acuity_M))/Cap_Doc,1)+CEILING((0.99)*(Arr_E*(1+0.5*Acuity_E))/Cap_Doc,1)+CEILING((0.99)*(Arr_N*(1+0.5*Acuity_N))/Cap_Doc,1)),Avail_Doc)))*Cap_Doc+(MAX(0,((CEILING((0.99)*(Arr_M)/Cap_Nurse,1)+CEILING((0.99)*(Arr_E)/Cap_Nurse,1)+CEILING((0.99)*(Arr_N)/Cap_Nurse,1)))-Avail_Nurse-(OTCapPct)*MIN((CEILING((0.99)*(Arr_M)/Cap_Nurse,1)+CEILING((0.99)*(Arr_E)/Cap_Nurse,1)+CEILING((0.99)*(Arr_N)/Cap_Nurse,1)),Avail_Nurse)))*Cap_Nurse+(MAX(0,((CEILING((0.99)*(Arr_M)/Cap_Tech,1)+CEILING((0.99)*(Arr_E)/Cap_Tech,1)+CEILING((0.99)*(Arr_N)/Cap_Tech,1)))-Avail_Tech-(OTCapPct)*MIN((CEILING((0.99)*(Arr_M)/Cap_Tech,1)+CEILING((0.99)*(Arr_E)/Cap_Tech,1)+CEILING((0.99)*(Arr_N)/Cap_Tech,1)),Avail_Tech)))*Cap_Tech+(MAX(0,(0.99)*Arr_M-(BedsAdded+BedsCurrent)*ShiftHours/BedHr_M)+MAX(0,(0.99)*Arr_E-(BedsAdded+BedsCurrent)*ShiftHours/BedHr_E)+MAX(0,(0.99)*Arr_N-(BedsAdded+BedsCurrent)*ShiftHours/BedHr_N))+(MAX(0,(0.99)*Arr_M*Acuity_M-(ImgBase+(ImgExpOn)*ImgExpAdd))+MAX(0,(0.99)*Arr_E*Acuity_E-(ImgBase+(ImgExpOn)*ImgExpAdd))+MAX(0,(0.99)*Arr_N*Acuity_N-(ImgBase+(ImgExpOn)*ImgExpAdd)))+(MAX(0,(0.99)*Arr_M-(LabBase+(LabExpOn)*LabExpAdd))+MAX(0,(0.99)*Arr_E-(LabBase+(LabExpOn)*LabExpAdd))+MAX(0,(0.99)*Arr_N-(LabBase+(LabExpOn)*LabExpAdd))) -> 33.8 | E10: =B10-B11 -> 99180
A11: CURRENT (Inputs sheet) | B11: =((MIN((CEILING((ServiceTarget)*(Arr_M*(1+0.5*Acuity_M))/Cap_Doc,1)+CEILING((ServiceTarget)*(Arr_E*(1+0.5*Acuity_E))/Cap_Doc,1)+CEILING((ServiceTarget)*(Arr_N*(1+0.5*Acuity_N))/Cap_Doc,1)),Avail_Doc))*RegCost_Doc+(MIN(MAX((CEILING((ServiceTarget)*(Arr_M*(1+0.5*Acuity_M))/Cap_Doc,1)+CEILING((ServiceTarget)*(Arr_E*(1+0.5*Acuity_E))/Cap_Doc,1)+CEILING((ServiceTarget)*(Arr_N*(1+0.5*Acuity_N))/Cap_Doc,1))-Avail_Doc,0),(OTCapPct)*MIN((CEILING((ServiceTarget)*(Arr_M*(1+0.5*Acuity_M))/Cap_Doc,1)+CEILING((ServiceTarget)*(Arr_E*(1+0.5*Acuity_E))/Cap_Doc,1)+CEILING((ServiceTarget)*(Arr_N*(1+0.5*Acuity_N))/Cap_Doc,1)),Avail_Doc)))*OTCost_Doc+(MIN((CEILING((ServiceTarget)*(Arr_M)/Cap_Nurse,1)+CEILING((ServiceTarget)*(Arr_E)/Cap_Nurse,1)+CEILING((ServiceTarget)*(Arr_N)/Cap_Nurse,1)),Avail_Nurse))*RegCost_Nurse+(MIN(MAX((CEILING((ServiceTarget)*(Arr_M)/Cap_Nurse,1)+CEILING((ServiceTarget)*(Arr_E)/Cap_Nurse,1)+CEILING((ServiceTarget)*(Arr_N)/Cap_Nurse,1))-Avail_Nurse,0),(OTCapPct)*MIN((CEILING((ServiceTarget)*(Arr_M)/Cap_Nurse,1)+CEILING((ServiceTarget)*(Arr_E)/Cap_Nurse,1)+CEILING((ServiceTarget)*(Arr_N)/Cap_Nurse,1)),Avail_Nurse)))*OTCost_Nurse+(MIN((CEILING((ServiceTarget)*(Arr_M)/Cap_Tech,1)+CEILING((ServiceTarget)*(Arr_E)/Cap_Tech,1)+CEILING((ServiceTarget)*(Arr_N)/Cap_Tech,1)),Avail_Tech))*RegCost_Tech+(MIN(MAX((CEILING((ServiceTarget)*(Arr_M)/Cap_Tech,1)+CEILING((ServiceTarget)*(Arr_E)/Cap_Tech,1)+CEILING((ServiceTarget)*(Arr_N)/Cap_Tech,1))-Avail_Tech,0),(OTCapPct)*MIN((CEILING((ServiceTarget)*(Arr_M)/Cap_Tech,1)+CEILING((ServiceTarget)*(Arr_E)/Cap_Tech,1)+CEILING((ServiceTarget)*(Arr_N)/Cap_Tech,1)),Avail_Tech)))*OTCost_Tech)+((BedsAdded)*BedCostPerBed+(ImgExpOn)*ImgExpCost+(LabExpOn)*LabExpCost)+(((MAX(0,((CEILING((ServiceTarget)*(Arr_M*(1+0.5*Acuity_M))/Cap_Doc,1)+CEILING((ServiceTarget)*(Arr_E*(1+0.5*Acuity_E))/Cap_Doc,1)+CEILING((ServiceTarget)*(Arr_N*(1+0.5*Acuity_N))/Cap_Doc,1)))-Avail_Doc-(OTCapPct)*MIN((CEILING((ServiceTarget)*(Arr_M*(1+0.5*Acuity_M))/Cap_Doc,1)+CEILING((ServiceTarget)*(Arr_E*(1+0.5*Acuity_E))/Cap_Doc,1)+CEILING((ServiceTarget)*(Arr_N*(1+0.5*Acuity_N))/Cap_Doc,1)),Avail_Doc)))*Cap_Doc+(MAX(0,((CEILING((ServiceTarget)*(Arr_M)/Cap_Nurse,1)+CEILING((ServiceTarget)*(Arr_E)/Cap_Nurse,1)+CEILING((ServiceTarget)*(Arr_N)/Cap_Nurse,1)))-Avail_Nurse-(OTCapPct)*MIN((CEILING((ServiceTarget)*(Arr_M)/Cap_Nurse,1)+CEILING((ServiceTarget)*(Arr_E)/Cap_Nurse,1)+CEILING((ServiceTarget)*(Arr_N)/Cap_Nurse,1)),Avail_Nurse)))*Cap_Nurse+(MAX(0,((CEILING((ServiceTarget)*(Arr_M)/Cap_Tech,1)+CEILING((ServiceTarget)*(Arr_E)/Cap_Tech,1)+CEILING((ServiceTarget)*(Arr_N)/Cap_Tech,1)))-Avail_Tech-(OTCapPct)*MIN((CEILING((ServiceTarget)*(Arr_M)/Cap_Tech,1)+CEILING((ServiceTarget)*(Arr_E)/Cap_Tech,1)+CEILING((ServiceTarget)*(Arr_N)/Cap_Tech,1)),Avail_Tech)))*Cap_Tech+(MAX(0,(ServiceTarget)*Arr_M-(BedsAdded+BedsCurrent)*ShiftHours/BedHr_M)+MAX(0,(ServiceTarget)*Arr_E-(BedsAdded+BedsCurrent)*ShiftHours/BedHr_E)+MAX(0,(ServiceTarget)*Arr_N-(BedsAdded+BedsCurrent)*ShiftHours/BedHr_N))+(MAX(0,(ServiceTarget)*Arr_M*Acuity_M-(ImgBase+(ImgExpOn)*ImgExpAdd))+MAX(0,(ServiceTarget)*Arr_E*Acuity_E-(ImgBase+(ImgExpOn)*ImgExpAdd))+MAX(0,(ServiceTarget)*Arr_N*Acuity_N-(ImgBase+(ImgExpOn)*ImgExpAdd)))+(MAX(0,(ServiceTarget)*Arr_M-(LabBase+(LabExpOn)*LabExpAdd))+MAX(0,(ServiceTarget)*Arr_E-(LabBase+(LabExpOn)*LabExpAdd))+MAX(0,(ServiceTarget)*Arr_N-(LabBase+(LabExpOn)*LabExpAdd))))*(PenUncovered*(1-DivertShare)+PenDiverted*DivertShare)) -> 466610 | C11: =1-((MAX(0,((CEILING((ServiceTarget)*(Arr_M*(1+0.5*Acuity_M))/Cap_Doc,1)+CEILING((ServiceTarget)*(Arr_E*(1+0.5*Acuity_E))/Cap_Doc,1)+CEILING((ServiceTarget)*(Arr_N*(1+0.5*Acuity_N))/Cap_Doc,1)))-Avail_Doc-(OTCapPct)*MIN((CEILING((ServiceTarget)*(Arr_M*(1+0.5*Acuity_M))/Cap_Doc,1)+CEILING((ServiceTarget)*(Arr_E*(1+0.5*Acuity_E))/Cap_Doc,1)+CEILING((ServiceTarget)*(Arr_N*(1+0.5*Acuity_N))/Cap_Doc,1)),Avail_Doc)))*Cap_Doc+(MAX(0,((CEILING((ServiceTarget)*(Arr_M)/Cap_Nurse,1)+CEILING((ServiceTarget)*(Arr_E)/Cap_Nurse,1)+CEILING((ServiceTarget)*(Arr_N)/Cap_Nurse,1)))-Avail_Nurse-(OTCapPct)*MIN((CEILING((ServiceTarget)*(Arr_M)/Cap_Nurse,1)+CEILING((ServiceTarget)*(Arr_E)/Cap_Nurse,1)+CEILING((ServiceTarget)*(Arr_N)/Cap_Nurse,1)),Avail_Nurse)))*Cap_Nurse+(MAX(0,((CEILING((ServiceTarget)*(Arr_M)/Cap_Tech,1)+CEILING((ServiceTarget)*(Arr_E)/Cap_Tech,1)+CEILING((ServiceTarget)*(Arr_N)/Cap_Tech,1)))-Avail_Tech-(OTCapPct)*MIN((CEILING((ServiceTarget)*(Arr_M)/Cap_Tech,1)+CEILING((ServiceTarget)*(Arr_E)/Cap_Tech,1)+CEILING((ServiceTarget)*(Arr_N)/Cap_Tech,1)),Avail_Tech)))*Cap_Tech+(MAX(0,(ServiceTarget)*Arr_M-(BedsAdded+BedsCurrent)*ShiftHours/BedHr_M)+MAX(0,(ServiceTarget)*Arr_E-(BedsAdded+BedsCurrent)*ShiftHours/BedHr_E)+MAX(0,(ServiceTarget)*Arr_N-(BedsAdded+BedsCurrent)*ShiftHours/BedHr_N))+(MAX(0,(ServiceTarget)*Arr_M*Acuity_M-(ImgBase+(ImgExpOn)*ImgExpAdd))+MAX(0,(ServiceTarget)*Arr_E*Acuity_E-(ImgBase+(ImgExpOn)*ImgExpAdd))+MAX(0,(ServiceTarget)*Arr_N*Acuity_N-(ImgBase+(ImgExpOn)*ImgExpAdd)))+(MAX(0,(ServiceTarget)*Arr_M-(LabBase+(LabExpOn)*LabExpAdd))+MAX(0,(ServiceTarget)*Arr_E-(LabBase+(LabExpOn)*LabExpAdd))+MAX(0,(ServiceTarget)*Arr_N-(LabBase+(LabExpOn)*LabExpAdd))))/(Arr_M+Arr_E+Arr_N) -> 0.91037037 | D11: =(MAX(0,((CEILING((ServiceTarget)*(Arr_M*(1+0.5*Acuity_M))/Cap_Doc,1)+CEILING((ServiceTarget)*(Arr_E*(1+0.5*Acuity_E))/Cap_Doc,1)+CEILING((ServiceTarget)*(Arr_N*(1+0.5*Acuity_N))/Cap_Doc,1)))-Avail_Doc-(OTCapPct)*MIN((CEILING((ServiceTarget)*(Arr_M*(1+0.5*Acuity_M))/Cap_Doc,1)+CEILING((ServiceTarget)*(Arr_E*(1+0.5*Acuity_E))/Cap_Doc,1)+CEILING((ServiceTarget)*(Arr_N*(1+0.5*Acuity_N))/Cap_Doc,1)),Avail_Doc)))*Cap_Doc+(MAX(0,((CEILING((ServiceTarget)*(Arr_M)/Cap_Nurse,1)+CEILING((ServiceTarget)*(Arr_E)/Cap_Nurse,1)+CEILING((ServiceTarget)*(Arr_N)/Cap_Nurse,1)))-Avail_Nurse-(OTCapPct)*MIN((CEILING((ServiceTarget)*(Arr_M)/Cap_Nurse,1)+CEILING((ServiceTarget)*(Arr_E)/Cap_Nurse,1)+CEILING((ServiceTarget)*(Arr_N)/Cap_Nurse,1)),Avail_Nurse)))*Cap_Nurse+(MAX(0,((CEILING((ServiceTarget)*(Arr_M)/Cap_Tech,1)+CEILING((ServiceTarget)*(Arr_E)/Cap_Tech,1)+CEILING((ServiceTarget)*(Arr_N)/Cap_Tech,1)))-Avail_Tech-(OTCapPct)*MIN((CEILING((ServiceTarget)*(Arr_M)/Cap_Tech,1)+CEILING((ServiceTarget)*(Arr_E)/Cap_Tech,1)+CEILING((ServiceTarget)*(Arr_N)/Cap_Tech,1)),Avail_Tech)))*Cap_Tech+(MAX(0,(ServiceTarget)*Arr_M-(BedsAdded+BedsCurrent)*ShiftHours/BedHr_M)+MAX(0,(ServiceTarget)*Arr_E-(BedsAdded+BedsCurrent)*ShiftHours/BedHr_E)+MAX(0,(ServiceTarget)*Arr_N-(BedsAdded+BedsCurrent)*ShiftHours/BedHr_N))+(MAX(0,(ServiceTarget)*Arr_M*Acuity_M-(ImgBase+(ImgExpOn)*ImgExpAdd))+MAX(0,(ServiceTarget)*Arr_E*Acuity_E-(ImgBase+(ImgExpOn)*ImgExpAdd))+MAX(0,(ServiceTarget)*Arr_N*Acuity_N-(ImgBase+(ImgExpOn)*ImgExpAdd)))+(MAX(0,(ServiceTarget)*Arr_M-(LabBase+(LabExpOn)*LabExpAdd))+MAX(0,(ServiceTarget)*Arr_E-(LabBase+(LabExpOn)*LabExpAdd))+MAX(0,(ServiceTarget)*Arr_N-(LabBase+(LabExpOn)*LabExpAdd))) -> 24.2
A13: 2. Overtime Cap Sensitivity
A14: OT Cap (% of regular) | B14: Total Daily Cost | C14: Coverage % | D14: Uncovered Patients/Day | E14: Δ Cost vs Current
